Workbook

Sheet CONSOLIDADO
A3: CONSOLIDADO DEL PORCENTAJE DEL CUMPLIMIENTO DEL AISLAMIENTO CAC Santa Bàrbara BD COMITÉ DE INFECCIONES
A4: año | B4: ENE | C4: FEB | D4: MAR | E4: ABR | F4: MAY | G4: JUN | H4: JUL | I4: AGO | J4: SEP | K4: OCT | L4: NOV | M4: DIC | N4: Promedio
A5: 2022 | B5: 0.89130435 | C5: 0.94594595 | D5: 1 | E5: 0.81818182 | F5: 0.85 | G5: 0.94366197 | H5: 0.85416667 | I5: 0.82926829 | J5: 0.82222222 | K5: 0.87037037 | L5: 0.86 | M5: 1 | N5: =AVERAGE(C5:M5) -> 0.89034703
A6: 2023 | B6: 0.78947368 | C6: 0.77142857 | D6: 0.85245902 | E6: 0.87755102 | F6: 0.89473684 | G6: 0.87301587 | H6: 0.84615385 | I6: 0.85714286 | J6: 0.89230769 | K6: 0.89855072 | L6: 0.88888889 | M6: 0.86363636 | N6: =AVERAGE(C6:M6) -> 0.86507925
A7: 2024 | B7: 0.82608696 | C7: 0.83783784 | D7: 0.80645161 | E7: 0.88 | F7: 0.82222222 | G7: 0.8019802 | H7: 0.82692308 | I7: 0.82758621 | J7: 0.85 | K7: 0.82051282 | L7: 0.86 | M7: 0.85714286 | N7: =AVERAGE(C7:M7) -> 0.83551426
A8: 2025 | B8: 0.83 | C8: 0.84 | D8: 0.8 | E8: 0.83 | F8: 0.83 | G8: 0.81 | H8: 0.83 | I8: 0.85 | J8: 0.84 | K8: 0.87 | L8: 0.8 | M8: 0.82 | N8: =AVERAGE(C8:M8) -> 0.82909091
A9: 2026 | B9: ='CUMPLIMIENTO 2026'!B5 -> 0.85 | C9: ='CUMPLIMIENTO 2026'!C5 -> #REF! | D9: ='CUMPLIMIENTO 2026'!D5 -> #REF! | E9: ='CUMPLIMIENTO 2026'!E5 -> #REF! | F9: ='CUMPLIMIENTO 2026'!F5 -> #REF! | G9: ='CUMPLIMIENTO 2026'!G5 -> #REF! | H9: ='CUMPLIMIENTO 2026'!H5 -> #REF! | I9: ='CUMPLIMIENTO 2026'!I5 -> #REF! | ... M9: ='CUMPLIMIENTO 2026'!M5 -> #REF! | N9: =AVERAGE(C9:M9) -> #REF!
A10: 2027 | N10: =AVERAGE(C10:M10) -> #DIV/0!
A11: 2028 | N11: =AVERAGE(C11:M11) -> #DIV/0!
A12: 2029 | N12: =AVERAGE(C12:M12) -> #DIV/0!
A13: 2030 | N13: =AVERAGE(C13:M13) -> #DIV/0!
A14: 2031 | N14: =AVERAGE(C14:M14) -> #DIV/0!
A15: 2032 | N15: =AVERAGE(C15:M15) -> #DIV/0!
A16: 2033 | N16: =AVERAGE(C16:M16) -> #DIV/0!
A17: 2034 | N17: =AVERAGE(C17:M17) -> #DIV/0!
A19: META | B19: 1 | C19: 1 | D19: 1 | E19: 1 | F19: 1 | G19: 1 | H19: 1 | I19: 1 | J19: 1 | K19: 1 | L19: 1 | M19: 1

Sheet CUMPLIMIENTO 2026
A1: ADHERENCIA DE AISLAMIENTO CAC Santa Bàrbara AÑO 2026 BD COMITÉ DE INFECCION
A2: SERVICIO | B2: ENE | C2: FEB | D2: MAR | E2: ABR | F2: MAY | G2: JUN | H2: JUL | I2: AGO | J2: SEP | K2: OCT | L2: NOV | M2: DIC | N2: PROMEDIO
A3: OBSERVADOS | B3: ='ENE 2026'!C6 -> 40 | C3: =#REF! -> #REF! | D3: =#REF! -> #REF! | E3: =#REF! -> #REF! | F3: =#REF! -> #REF! | G3: =#REF! -> #REF! | H3: =#REF! -> #REF! | I3: =#REF! -> #REF! | J3: =#REF! -> #REF! | ... M3: =#REF! -> #REF! | N3: =AVERAGE(B3:M3) -> #REF!
A4: CUMPLEN | B4: ='ENE 2026'!B6 -> 34 | C4: =#REF! -> #REF! | D4: =#REF! -> #REF! | E4: =#REF! -> #REF! | F4: =#REF! -> #REF! | G4: =#REF! -> #REF! | H4: =#REF! -> #REF! | I4: =#REF! -> #REF! | J4: =#REF! -> #REF! | ... M4: =#REF! -> #REF! | N4: =AVERAGE(B4:M4) -> #REF!
A5: 20.26 | B5: =B4/B3 -> 0.85 | C5: =C4/C3 -> #REF! | D5: =D4/D3 -> #REF! | E5: =E4/E3 -> #REF! | F5: =F4/F3 -> #REF! | G5: =G4/G3 -> #REF! | H5: =H4/H3 -> #REF! | I5: =I4/I3 -> #REF! | ... M5: =M4/M3 -> #REF! | N5: =AVERAGE(B5:M5) -> #REF!
A6: META | B6: 0.9 | C6: 0.9 | D6: 0.9 | E6: 0.9 | F6: 0.9 | G6: 0.9 | H6: 0.9 | I6: 0.9 | J6: 0.9 | K6: 0.9 | L6: 0.9 | M6: 0.9 | N6: =AVERAGE(B6:M6) -> 0.9
A8: INICIA MEDICIÓN febrero 2022
A9: % CUMPLIMIENTO 1ER TRIMESTRE | B9: =(B4+C4+D4)/(B3+C3+D3) -> #REF!
A10: % CUMPLIMIENTO 2DO TRIMESTRE | B10: =(E4+F4+G4)/(E3+F3+G3) -> #REF!
A11: % CUMPLIMIENTO 3RO TRIMESTRE | B11: =(H4+I4+J4)/(H3+I3+J3) -> #REF!
A12: % CUMPLIMIENTO 4TO TRIMESTRE | B12: =(K4+L4+M4)/(K3+L3+M3) -> #REF!
A13: No se observo
A16: ADHERENCIA DE AISLAMIENTO SEGÚN SERVICIO CAC Santa Bàrbara AÑO 2026 BD COMITÉ DE INFECCION
A17: SERVICIO | B17: ENE | C17: FEB | D17: MAR | E17: ABR | F17: MAY | G17: JUN | H17: JUL | I17: AGO | J17: SEP | K17: OCT | L17: NOV | M17: DIC | N17: promedio I trim | O17: promedio II trim | P17: promedio III trim | Q17: promedio IV trim
A18: HOSPITALIZACIÓN 2 | B18: ='ENE 2026'!D2 -> 1 | C18: =#REF! -> #REF! | D18: =#REF! -> #REF! | E18: #REF! | F18: =#REF! -> #REF! | G18: =#REF! -> #REF! | H18: =#REF! -> #REF! | I18: =#REF! -> #REF! | J18: =#REF! -> #REF! | K18: =#REF! -> #REF! | L18: =#REF! -> #REF! | M18: =#REF! -> #REF! | N18: =AVERAGE(B18:B18:D18) -> #REF!
A19: HOSPITALIZACIÓN | B19: ='ENE 2026'!D3 -> 0.83333333 | C19: =#REF! -> #REF! | D19: =#REF! -> #REF! | E19: #REF! | F19: =#REF! -> #REF! | G19: =#REF! -> #REF! | H19: =#REF! -> #REF! | I19: =#REF! -> #REF! | J19: =#REF! -> #REF! | K19: =#REF! -> #REF! | L19: =#REF! -> #REF! | M19: =#REF! -> #REF! | N19: =AVERAGE(B19:B19:D19) -> 0.9010989
A20: UCI | B20: ='ENE 2026'!D4 -> 0.88888889 | C20: =#REF! -> #REF! | D20: =#REF! -> #REF! | E20: #REF! | F20: =#REF! -> #REF! | G20: =#REF! -> #REF! | H20: =#REF! -> #REF! | I20: =#REF! -> #REF! | J20: =#REF! -> #REF! | K20: =#REF! -> #REF! | L20: =#REF! -> #REF! | M20: =#REF! -> #REF! | N20: =AVERAGE(B20:B20:D20) -> 0.9010989
A21: URGENCIAS | B21: ='ENE 2026'!D5 -> 0.81818182 | C21: =#REF! -> #REF! | D21: =#REF! -> #REF! | E21: #REF! | F21: =#REF! -> #REF! | G21: =#REF! -> #REF! | H21: =#REF! -> #REF! | I21: =#REF! -> #REF! | J21: =#REF! -> #REF! | K21: =#REF! -> #REF! | L21: =#REF! -> #REF! | M21: =#REF! -> #REF! | N21: =AVERAGE(B21:B21:D21) -> 0.9010989
A22: META | B22: 0.9 | C22: 0.9 | D22: 0.9 | E22: 0.9 | F22: 0.9 | G22: 0.9 | H22: 0.9 | I22: 0.9 | J22: 0.9 | K22: 0.9 | L22: 0.9 | M22: 0.9 | N22: =AVERAGE(B22:B22:D22) -> 0.9010989
A35: ADHERENCIA DE AISLAMIENTOS SEGÚN PROFESION CAC Santa Bárbara AÑO 2026
A36: PROFESION | B36: ENE | C36: FEB | D36: MAR | E36: ABR | F36: MAY | G36: JUN | H36: JUL | I36: AGO | J36: SEP | K36: OCT | L36: NOV | M36: DIC
A37: AUXILIAR | B37: ='ENE 2026'!D9 -> 0.86363636 | C37: =#REF! -> #REF! | D37: =#REF! -> #REF! | E37: #REF! | F37: =#REF! -> #REF! | G37: =#REF! -> #REF! | H37: =#REF! -> #REF! | I37: =#REF! -> #REF! | J37: =#REF! -> #REF! | K37: =#REF! -> #REF! | L37: =#REF! -> #REF! | M37: =#REF! -> #REF!
A38: ENFERMERA (O) | B38: ='ENE 2026'!D10 -> 1 | C38: =#REF! -> #REF! | D38: =#REF! -> #REF! | E38: #REF! | F38: =#REF! -> #REF! | G38: =#REF! -> #REF! | H38: =#REF! -> #REF! | I38: =#REF! -> #REF! | J38: =#REF! -> #REF! | K38: =#REF! -> #REF! | L38: =#REF! -> #REF! | M38: =#REF! -> #REF!
A39: MEDICO | B39: ='ENE 2026'!D11 -> 0.85714286 | C39: =#REF! -> #REF! | D39: =#REF! -> #REF! | E39: #REF! | F39: =#REF! -> #REF! | G39: =#REF! -> #REF! | H39: =#REF! -> #REF! | I39: =#REF! -> #REF! | J39: =#REF! -> #REF! | K39: =#REF! -> #REF! | L39: =#REF! -> #REF! | M39: =#REF! -> #REF!
A40: META | B40: 0.9 | C40: 0.9 | D40: 0.9 | E40: 0.9 | F40: 0.9 | G40: 0.9 | H40: 0.9 | I40: 0.9 | J40: 0.9 | K40: 0.9 | L40: 0.9 | M40: 0.9
A50: ADHERENCIA PROTOCOLO DE AISLAMIENTO SERVICIO DE HOSPITALIZACION CACSB 2023 - 2024 - 2025 - 2026 BD COMITÉ DE INFECCION
A51: HOSPITALIZACIÓN | B51: ENE | C51: FEB | D51: MAR | E51: ABR | F51: MAY | G51: JUN | H51: JUL | I51: AGO | J51: SEP | K51: OCT | L51: NOV | M51: DIC | N51: promedio I trim | O51: promedio II trim | P51: promedio III trim | Q51: promedio IV trim
A52: 2023 | B52: 0.78 | C52: 0.7 | D52: 0.85 | E52: 0.88 | F52: 0.9 | G52: 0.9 | H52: 0.86 | I52: 0.86 | J52: 0.89 | K52: 0.88 | L52: 0.91 | M52: 0.82 | N52: =AVERAGE(B52:D52) -> 0.77666667 | O52: =AVERAGE(E52:G52) -> 0.89333333 | P52: =AVERAGE(H52:J52) -> 0.87 | Q52: =AVERAGE(K52:M52) -> 0.87
A53: 2024 | B53: 0.83333333 | C53: 0.8 | D53: 0.8125 | E53: 0.88888889 | F53: 0.80882353 | G53: 0.79365079 | H53: 0.83333333 | I53: 0.8 | J53: 0.84615385 | K53: 0.81818182 | L53: 0.87096774 | M53: 0.88461538 | N53: =AVERAGE(B53:D53) -> 0.81527778 | O53: =AVERAGE(E53:G53) -> 0.8304544 | P53: =AVERAGE(H53:J53) -> 0.82649573 | Q53: =AVERAGE(K53:M53) -> 0.85792165
A54: 2025 | B54: 0.84 | C54: 0.83 | D54: 0.8 | E54: 0.82 | F54: 0.83 | G54: 0.75 | H54: 0.82 | I54: 0.8 | J54: 0.83 | K54: 0.82 | L54: 0.8 | M54: 0.8
A55: 2026 | B55: =B19 -> 0.83333333 | C55: =C20 -> #REF! | D55: =D20 -> #REF! | E55: =E20 -> #REF! | F55: =F20 -> #REF! | G55: =G20 -> #REF! | H55: =H20 -> #REF! | I55: =I20 -> #REF! | J55: =J20 -> #REF! | ... M55: =M20 -> #REF! | N55: =AVERAGE(B55:D55) -> #REF! | O55: =AVERAGE(E55:G55) -> #REF! | P55: =AVERAGE(H55:J55) -> #REF! | Q55: =AVERAGE(K55:M55) -> #REF!
A56: META | B56: 0.9 | C56: 0.9 | D56: 0.9 | E56: 0.9 | F56: 0.9 | G56: 0.9 | H56: 0.9 | I56: 0.9 | J56: 0.9 | K56: 0.9 | L56: 0.9 | M56: 0.9
A74: ADHERENCIA SEGÚN TIPO DE AISLAMIENTO HOSPITALIZACIÓN CAC Santa Bàrbara AÑO 2024
A75: TIPO DE AISLAMIENTO | B75: ENE | C75: FEB | D75: MAR | E75: ABR | F75: MAY | G75: JUN | H75: JUL | I75: AGO | J75: SEP | K75: OCT | L75: NOV | M75: DIC
A76: COHORTIZACIÓN | B76: #REF! | C76: #REF! | D76: #REF! | E76: #REF! | F76: #REF! | G76: #REF! | H76: ='[1]JUL 2026'!D16 -> #REF! | I76: #REF! | J76: #REF! | K76: #REF! | L76: #REF! | M76: #REF!
A77: CONTACTO | B77: #REF! | C77: #REF! | D77: #REF! | E77: #REF! | F77: #REF! | G77: #REF! | H77: ='[1]JUL 2026'!D13 -> #REF! | I77: #REF! | J77: #REF! | K77: #REF! | L77: #REF! | M77: #REF!
A78: GOTAS | B78: #REF! | C78: #REF! | D78: #REF! | E78: #REF! | F78: #REF! | G78: #REF! | H78: #REF! | I78: #REF! | J78: #REF! | K78: #REF! | L78: #REF! | M78: #REF!
A79: VIA AEREA | B79: #REF! | C79: #REF! | D79: #REF! | E79: #REF! | F79: #REF! | G79: #REF! | H79: #REF! | I79: #REF! | J79: #REF! | K79: #REF! | L79: #REF! | M79: #REF!
A80: META | B80: 0.9 | C80: 0.9 | D80: 0.9 | E80: 0.9 | F80: 0.9 | G80: 0.9 | H80: 0.9 | I80: 0.9 | J80: 0.9 | K80: 0.9 | L80: 0.9 | M80: 0.9
J82: NO HUBO
...

Sheet ENE 2026
A1: ADHERENCIA DE AISLAMIENTO SEGÚN SERVICIO CAC Santa Bàrbara AÑO 2024 | B1: NUMERO DE ADHERENCIA S (NUMERADOR) | C1: NUMERO TOTAL DE OBSERVACIONES POR SERVICIO (DENOMINADOR) | D1: PORCENTAJE ADHERENCIA | F1: FECHA | G1: SERVICIO | H1: PROFESIONAL | I1: TIPO DE AISLAMIENTO | J1: TIENE AFICHE | K1: BISUTERIA | L1: HIGIENE DE MANOS PREVIO | M1: USO DE BATA | N1: TIPO DE TAPABOCA | O1: USO DE GORRO | P1: USO DE GUANTE | Q1: CUELGA BATA | R1: HIGIENE DE MANOS DESPUÉS | S1: ADHERENCIA | T1: NOMBRE EVALUADO | U1: OBSERVACION
A2: ADHERENCIA GENERAL HOSPITALIZACIÓN 2 | B2: =COUNTIFS(G:G,"HOSPITALIZACIÓN 2 ",S:S,"CUMPLE") -> 2 | C2: =COUNTIFS(G:G,"HOSPITALIZACIÓN 2 ") -> 2 | D2: =IFERROR(COUNTIFS(G:G,"HOSPITALIZACIÓN 2 ",S:S,"CUMPLE")/COUNTIFS(G:G,"HOSPITALIZACIÓN 2 "),0) -> 1 | E2: 1 | F2: 46024 | G2: HOSPITALIZACIÓN | H2: AUXILIAR | I2: COHORTIZACIÓN | J2: SI | K2: NO | L2: SI | M2: SI | N2: QUIRURGICO | O2: SI | P2: SI | Q2: SI | R2: SI | S2: =IF(I2="CONTACTO",IF(COUNTIF(J2,"NO")+COUNTIF(K2,"SI")+COUNTIF(L2,"NO")+COUNTIF(M2,"NO")+COUNTIF(R2,"NO")=0,"CUMPLE","NO CUMPLE"),IF(I2="VIA AEREA",IF(COUNTIF(K2,"SI")+COUNTIF(L2,"NO")+(COUNTIF(N2,"ALTA EFICIENCIA")-1)+COUNTIF(R2,"NO")=0,"CUMPLE","NO CUMPLE"),IF(I2="VIA AEREA",IF(COUNTIF(J2,"NO")+COUNTIF(K2,"SI")+COUNTIF(L2,"NO")+(COUNTIF(N2,"ALTA EFICIENCIA")-1)+COUNTIF(R2,"NO")=0,"CUMPLE","NO CUMPLE"),IF(I2="GOTAS",IF(COUNTIF(J2,"NO")+COUNTIF(K2,"SI")+COUNTIF(L2,"NO")+(COUNTIF(N2,"ALTA EFICIENCIA")-1)+COUNTIF(R2,"NO")=0,"CUMPLE","NO CUMPLE"),IF(I2="COHORTIZACIÓN",IF(COUNTIF(J2,"NO")+COUNTIF(K2,"SI")+COUNTIF(L2,"NO")+COUNTIF(M2,"NO")+(COUNTIF(N2,"QUIRURGICO")-1)+COUNTIF(M32,"NA")+COUNTIF(O2,"NO")+COUNTIF(P2,"NO")+COUNTIF(Q2,"NO")+COUNTIF(R2,"NO")=0,"CUMPLE","NO CUMPLE")))))) -> CUMPLE | T2: claudia gil | U2: 814 | X2: SERVICIO | Y2: PROFESIONAL | Z2: TIPO DE AISLAMIENTO | AA2: BISUTERÍA | AB2: BATA PUÑO | AC2: TIPO DE TAPABOCA
A3: ADHERENCIA GENERAL HOSPITALIZACIÓN | B3: =COUNTIFS(G:G,"HOSPITALIZACIÓN",S:S,"CUMPLE") -> 15 | C3: =COUNTIFS(G:G,"HOSPITALIZACIÓN") -> 18 | D3: =IFERROR(COUNTIFS(G:G,"HOSPITALIZACIÓN",S:S,"CUMPLE")/COUNTIFS(G:G,"HOSPITALIZACIÓN"),0) -> 0.83333333 | E3: 2 | F3: 46027 | G3: HOSPITALIZACIÓN | H3: AUXILIAR | I3: CONTACTO | J3: SI | K3: NO | L3: SI | M3: SI | N3: QUIRURGICO | O3: SI | P3: SI | Q3: SI | R3: SI | S3: =IF(I3="CONTACTO",IF(COUNTIF(J3,"NO")+COUNTIF(K3,"SI")+COUNTIF(L3,"NO")+COUNTIF(M3,"NO")+COUNTIF(R3,"NO")=0,"CUMPLE","NO CUMPLE"),IF(I3="VIA AEREA",IF(COUNTIF(K3,"SI")+COUNTIF(L3,"NO")+(COUNTIF(N3,"ALTA EFICIENCIA")-1)+COUNTIF(R3,"NO")=0,"CUMPLE","NO CUMPLE"),IF(I3="VIA AEREA",IF(COUNTIF(J3,"NO")+COUNTIF(K3,"SI")+COUNTIF(L3,"NO")+(COUNTIF(N3,"ALTA EFICIENCIA")-1)+COUNTIF(R3,"NO")=0,"CUMPLE","NO CUMPLE"),IF(I3="GOTAS",IF(COUNTIF(J3,"NO")+COUNTIF(K3,"SI")+COUNTIF(L3,"NO")+(COUNTIF(N3,"ALTA EFICIENCIA")-1)+COUNTIF(R3,"NO")=0,"CUMPLE","NO CUMPLE"),IF(I3="COHORTIZACIÓN",IF(COUNTIF(J3,"NO")+COUNTIF(K3,"SI")+COUNTIF(L3,"NO")+COUNTIF(M3,"NO")+(COUNTIF(N3,"QUIRURGICO")-1)+COUNTIF(M33,"NA")+COUNTIF(O3,"NO")+COUNTIF(P3,"NO")+COUNTIF(Q3,"NO")+COUNTIF(R3,"NO")=0,"CUMPLE","NO CUMPLE")))))) -> CUMPLE | T3: andres londoño
A4: ADHERENCIA GENERAL UCI | B4: =COUNTIFS(G:G,"UCI",S:S,"CUMPLE") -> 8 | C4: =COUNTIFS(G:G,"UCI") -> 9 | D4: =IFERROR(COUNTIFS(G:G,"UCI",S:S,"CUMPLE")/COUNTIFS(G:G,"UCI"),0) -> 0.88888889 | E4: 3 | F4: 46028 | G4: HOSPITALIZACIÓN | H4: AUXILIAR | I4: VIA AEREA | J4: SI | K4: NO | L4: SI | M4: NA | N4: ALTA EFICIENCIA | O4: NO | P4: NO | Q4: NA | R4: SI | S4: =IF(I4="CONTACTO",IF(COUNTIF(J4,"NO")+COUNTIF(K4,"SI")+COUNTIF(L4,"NO")+COUNTIF(M4,"NO")+COUNTIF(R4,"NO")=0,"CUMPLE","NO CUMPLE"),IF(I4="VIA AEREA",IF(COUNTIF(K4,"SI")+COUNTIF(L4,"NO")+(COUNTIF(N4,"ALTA EFICIENCIA")-1)+COUNTIF(R4,"NO")=0,"CUMPLE","NO CUMPLE"),IF(I4="VIA AEREA",IF(COUNTIF(J4,"NO")+COUNTIF(K4,"SI")+COUNTIF(L4,"NO")+(COUNTIF(N4,"ALTA EFICIENCIA")-1)+COUNTIF(R4,"NO")=0,"CUMPLE","NO CUMPLE"),IF(I4="GOTAS",IF(COUNTIF(J4,"NO")+COUNTIF(K4,"SI")+COUNTIF(L4,"NO")+(COUNTIF(N4,"ALTA EFICIENCIA")-1)+COUNTIF(R4,"NO")=0,"CUMPLE","NO CUMPLE"),IF(I4="COHORTIZACIÓN",IF(COUNTIF(J4,"NO")+COUNTIF(K4,"SI")+COUNTIF(L4,"NO")+COUNTIF(M4,"NO")+(COUNTIF(N4,"QUIRURGICO")-1)+COUNTIF(M34,"NA")+COUNTIF(O4,"NO")+COUNTIF(P4,"NO")+COUNTIF(Q4,"NO")+COUNTIF(R4,"NO")=0,"CUMPLE","NO CUMPLE")))))) -> CUMPLE | T4: john paredes | U4: 825
A5: ADHERENCIA GENERAL URGENCIAS | B5: =COUNTIFS(G:G,"URGENCIAS",S:S,"CUMPLE") -> 9 | C5: =COUNTIFS(G:G,"URGENCIAS") -> 11 | D5: =IFERROR(COUNTIFS(G:G,"URGENCIAS",S:S,"CUMPLE")/COUNTIFS(G:G,"URGENCIAS"),0) -> 0.81818182 | E5: 4 | F5: 46028 | G5: HOSPITALIZACIÓN | H5: AUXILIAR | I5: CONTACTO | J5: SI | K5: NO | L5: SI | M5: NO | N5: NO | O5: NO | P5: NO | Q5: NO | R5: SI | S5: NO CUMPLE | T5: claudia gil | U5: 827
A6: TOTAL | B6: =SUM(B2:B5) -> 34 | C6: =SUM(C2:C5) -> 40 | D6: =B6/C6 -> 0.85 | E6: 5 | F6: 46028 | G6: HOSPITALIZACIÓN 2 | H6: ENFERMERA (O) | I6: CONTACTO | J6: SI | K6: NO | L6: SI | M6: SI | N6: QUIRURGICO | O6: NO | P6: SI | Q6: SI | R6: SI | S6: =IF(I6="CONTACTO",IF(COUNTIF(J6,"NO")+COUNTIF(K6,"SI")+COUNTIF(L6,"NO")+COUNTIF(M6,"NO")+COUNTIF(R6,"NO")=0,"CUMPLE","NO CUMPLE"),IF(I6="VIA AEREA",IF(COUNTIF(K6,"SI")+COUNTIF(L6,"NO")+(COUNTIF(N6,"ALTA EFICIENCIA")-1)+COUNTIF(R6,"NO")=0,"CUMPLE","NO CUMPLE"),IF(I6="VIA AEREA",IF(COUNTIF(J6,"NO")+COUNTIF(K6,"SI")+COUNTIF(L6,"NO")+(COUNTIF(N6,"ALTA EFICIENCIA")-1)+COUNTIF(R6,"NO")=0,"CUMPLE","NO CUMPLE"),IF(I6="GOTAS",IF(COUNTIF(J6,"NO")+COUNTIF(K6,"SI")+COUNTIF(L6,"NO")+(COUNTIF(N6,"ALTA EFICIENCIA")-1)+COUNTIF(R6,"NO")=0,"CUMPLE","NO CUMPLE"),IF(I6="COHORTIZACIÓN",IF(COUNTIF(J6,"NO")+COUNTIF(K6,"SI")+COUNTIF(L6,"NO")+COUNTIF(M6,"NO")+(COUNTIF(N6,"QUIRURGICO")-1)+COUNTIF(M36,"NA")+COUNTIF(O6,"NO")+COUNTIF(P6,"NO")+COUNTIF(Q6,"NO")+COUNTIF(R6,"NO")=0,"CUMPLE","NO CUMPLE")))))) -> CUMPLE | T6: ALEXANDRA CALVO
E7: 6 | F7: 46028 | G7: UCI | H7: AUXILIAR | I7: CONTACTO | J7: SI | K7: NO | L7: SI | M7: SI | N7: QUIRURGICO | O7: NO | P7: SI | Q7: SI | R7: SI | S7: =IF(I7="CONTACTO",IF(COUNTIF(J7,"NO")+COUNTIF(K7,"SI")+COUNTIF(L7,"NO")+COUNTIF(M7,"NO")+COUNTIF(R7,"NO")=0,"CUMPLE","NO CUMPLE"),IF(I7="VIA AEREA",IF(COUNTIF(K7,"SI")+COUNTIF(L7,"NO")+(COUNTIF(N7,"ALTA EFICIENCIA")-1)+COUNTIF(R7,"NO")=0,"CUMPLE","NO CUMPLE"),IF(I7="VIA AEREA",IF(COUNTIF(J7,"NO")+COUNTIF(K7,"SI")+COUNTIF(L7,"NO")+(COUNTIF(N7,"ALTA EFICIENCIA")-1)+COUNTIF(R7,"NO")=0,"CUMPLE","NO CUMPLE"),IF(I7="GOTAS",IF(COUNTIF(J7,"NO")+COUNTIF(K7,"SI")+COUNTIF(L7,"NO")+(COUNTIF(N7,"ALTA EFICIENCIA")-1)+COUNTIF(R7,"NO")=0,"CUMPLE","NO CUMPLE"),IF(I7="COHORTIZACIÓN",IF(COUNTIF(J7,"NO")+COUNTIF(K7,"SI")+COUNTIF(L7,"NO")+COUNTIF(M7,"NO")+(COUNTIF(N7,"QUIRURGICO")-1)+COUNTIF(M37,"NA")+COUNTIF(O7,"NO")+COUNTIF(P7,"NO")+COUNTIF(Q7,"NO")+COUNTIF(R7,"NO")=0,"CUMPLE","NO CUMPLE")))))) -> CUMPLE | T7: JULIAN CUELLAR
A8: ADHERENCIA DE AISLAMIENTO POR TIPO DE PROFESIÓN GENERAL CAC Santa Bàrbara | E8: 7 | F8: 46029 | G8: UCI | H8: AUXILIAR | I8: VIA AEREA | J8: SI | K8: NO | L8: SI | M8: NA | N8: ALTA EFICIENCIA | O8: NO | P8: NO | Q8: NA | R8: SI | S8: =IF(I8="CONTACTO",IF(COUNTIF(J8,"NO")+COUNTIF(K8,"SI")+COUNTIF(L8,"NO")+COUNTIF(M8,"NO")+COUNTIF(R8,"NO")=0,"CUMPLE","NO CUMPLE"),IF(I8="VIA AEREA",IF(COUNTIF(K8,"SI")+COUNTIF(L8,"NO")+(COUNTIF(N8,"ALTA EFICIENCIA")-1)+COUNTIF(R8,"NO")=0,"CUMPLE","NO CUMPLE"),IF(I8="VIA AEREA",IF(COUNTIF(J8,"NO")+COUNTIF(K8,"SI")+COUNTIF(L8,"NO")+(COUNTIF(N8,"ALTA EFICIENCIA")-1)+COUNTIF(R8,"NO")=0,"CUMPLE","NO CUMPLE"),IF(I8="GOTAS",IF(COUNTIF(J8,"NO")+COUNTIF(K8,"SI")+COUNTIF(L8,"NO")+(COUNTIF(N8,"ALTA EFICIENCIA")-1)+COUNTIF(R8,"NO")=0,"CUMPLE","NO CUMPLE"),IF(I8="COHORTIZACIÓN",IF(COUNTIF(J8,"NO")+COUNTIF(K8,"SI")+COUNTIF(L8,"NO")+COUNTIF(M8,"NO")+(COUNTIF(N8,"QUIRURGICO")-1)+COUNTIF(M38,"NA")+COUNTIF(O8,"NO")+COUNTIF(P8,"NO")+COUNTIF(Q8,"NO")+COUNTIF(R8,"NO")=0,"CUMPLE","NO CUMPLE")))))) -> CUMPLE | T8: BRANDON CHAMORRO | U8: CI 4
A9: AUXILIAR | B9: =COUNTIFS(H:H,"AUXILIAR",S:S,"CUMPLE") -> 19 | C9: =COUNTIFS(H:H,"AUXILIAR") -> 22 | D9: =IFERROR(COUNTIFS(H:H,"AUXILIAR",S:S,"CUMPLE")/COUNTIFS(H:H,"AUXILIAR"),0) -> 0.86363636 | E9: 8 | F9: 46030 | G9: HOSPITALIZACIÓN | H9: MEDICO | I9: CONTACTO | J9: SI | K9: NO | L9: SI | M9: SI | N9: QUIRURGICO | O9: NO | P9: SI | Q9: SI | R9: SI | S9: =IF(I9="CONTACTO",IF(COUNTIF(J9,"NO")+COUNTIF(K9,"SI")+COUNTIF(L9,"NO")+COUNTIF(M9,"NO")+COUNTIF(R9,"NO")=0,"CUMPLE","NO CUMPLE"),IF(I9="VIA AEREA",IF(COUNTIF(K9,"SI")+COUNTIF(L9,"NO")+(COUNTIF(N9,"ALTA EFICIENCIA")-1)+COUNTIF(R9,"NO")=0,"CUMPLE","NO CUMPLE"),IF(I9="VIA AEREA",IF(COUNTIF(J9,"NO")+COUNTIF(K9,"SI")+COUNTIF(L9,"NO")+(COUNTIF(N9,"ALTA EFICIENCIA")-1)+COUNTIF(R9,"NO")=0,"CUMPLE","NO CUMPLE"),IF(I9="GOTAS",IF(COUNTIF(J9,"NO")+COUNTIF(K9,"SI")+COUNTIF(L9,"NO")+(COUNTIF(N9,"ALTA EFICIENCIA")-1)+COUNTIF(R9,"NO")=0,"CUMPLE","NO CUMPLE"),IF(I9="COHORTIZACIÓN",IF(COUNTIF(J9,"NO")+COUNTIF(K9,"SI")+COUNTIF(L9,"NO")+COUNTIF(M9,"NO")+(COUNTIF(N9,"QUIRURGICO")-1)+COUNTIF(M39,"NA")+COUNTIF(O9,"NO")+COUNTIF(P9,"NO")+COUNTIF(Q9,"NO")+COUNTIF(R9,"NO")=0,"CUMPLE","NO CUMPLE")))))) -> CUMPLE | T9: JUAN MEDINA | U9: 812
A10: ENFERMERA (O) | B10: =COUNTIFS(H:H,"ENFERMERA (O)",S:S,"CUMPLE") -> 2 | C10: =COUNTIFS(H:H,"ENFERMERA (O)") -> 2 | D10: =IFERROR(COUNTIFS(H:H,"ENFERMERA (O)",S:S,"CUMPLE")/COUNTIFS(H:H,"ENFERMERA (O)"),0) -> 1 | E10: 9 | F10: 45665 | G10: UCI | H10: AUXILIAR | I10: CONTACTO | J10: SI | K10: NO | L10: SI | M10: SI | N10: QUIRURGICO | O10: SI | P10: SI | Q10: SI | R10: SI | S10: =IF(I10="CONTACTO",IF(COUNTIF(J10,"NO")+COUNTIF(K10,"SI")+COUNTIF(L10,"NO")+COUNTIF(M10,"NO")+COUNTIF(R10,"NO")=0,"CUMPLE","NO CUMPLE"),IF(I10="VIA AEREA",IF(COUNTIF(K10,"SI")+COUNTIF(L10,"NO")+(COUNTIF(N10,"ALTA EFICIENCIA")-1)+COUNTIF(R10,"NO")=0,"CUMPLE","NO CUMPLE"),IF(I10="VIA AEREA",IF(COUNTIF(J10,"NO")+COUNTIF(K10,"SI")+COUNTIF(L10,"NO")+(COUNTIF(N10,"ALTA EFICIENCIA")-1)+COUNTIF(R10,"NO")=0,"CUMPLE","NO CUMPLE"),IF(I10="GOTAS",IF(COUNTIF(J10,"NO")+COUNTIF(K10,"SI")+COUNTIF(L10,"NO")+(COUNTIF(N10,"ALTA EFICIENCIA")-1)+COUNTIF(R10,"NO")=0,"CUMPLE","NO CUMPLE"),IF(I10="COHORTIZACIÓN",IF(COUNTIF(J10,"NO")+COUNTIF(K10,"SI")+COUNTIF(L10,"NO")+COUNTIF(M10,"NO")+(COUNTIF(N10,"QUIRURGICO")-1)+COUNTIF(M40,"NA")+COUNTIF(O10,"NO")+COUNTIF(P10,"NO")+COUNTIF(Q10,"NO")+COUNTIF(R10,"NO")=0,"CUMPLE","NO CUMPLE")))))) -> CUMPLE | T10: JUAN GOMEZ
A11: MEDICO | B11: =COUNTIFS(H:H,"MEDICO",S:S,"CUMPLE") -> 6 | C11: =COUNTIFS(H:H,"MEDICO") -> 7 | D11: =IFERROR(COUNTIFS(H:H,"MEDICO",S:S,"CUMPLE")/COUNTIFS(H:H,"MEDICO"),0) -> 0.85714286
A12: MEDICO ESP | B12: =COUNTIFS(H:H,"MEDICO ESP",S:S,"CUMPLE") -> 3 | C12: =COUNTIFS(H:H,"MEDICO ESP") -> 4 | D12: =IFERROR(COUNTIFS(H:H,"MEDICO ESP",S:S,"CUMPLE")/COUNTIFS(H:H,"MEDICO ESP"),0) -> 0.75 | E12: 10 | F12: 46030 | G12: UCI | H12: AUXILIAR | I12: COHORTIZACIÓN | J12: SI | K12: NO | L12: SI | M12: SI | N12: QUIRURGICO | O12: SI | P12: NO | Q12: SI | R12: SI | S12: =IF(I12="CONTACTO",IF(COUNTIF(J12,"NO")+COUNTIF(K12,"SI")+COUNTIF(L12,"NO")+COUNTIF(M12,"NO")+COUNTIF(R12,"NO")=0,"CUMPLE","NO CUMPLE"),IF(I12="VIA AEREA",IF(COUNTIF(K12,"SI")+COUNTIF(L12,"NO")+(COUNTIF(N12,"ALTA EFICIENCIA")-1)+COUNTIF(R12,"NO")=0,"CUMPLE","NO CUMPLE"),IF(I12="VIA AEREA",IF(COUNTIF(J12,"NO")+COUNTIF(K12,"SI")+COUNTIF(L12,"NO")+(COUNTIF(N12,"ALTA EFICIENCIA")-1)+COUNTIF(R12,"NO")=0,"CUMPLE","NO CUMPLE"),IF(I12="GOTAS",IF(COUNTIF(J12,"NO")+COUNTIF(K12,"SI")+COUNTIF(L12,"NO")+(COUNTIF(N12,"ALTA EFICIENCIA")-1)+COUNTIF(R12,"NO")=0,"CUMPLE","NO CUMPLE"),IF(I12="COHORTIZACIÓN",IF(COUNTIF(J12,"NO")+COUNTIF(K12,"SI")+COUNTIF(L12,"NO")+COUNTIF(M12,"NO")+(COUNTIF(N12,"QUIRURGICO")-1)+COUNTIF(M41,"NA")+COUNTIF(O12,"NO")+COUNTIF(P12,"NO")+COUNTIF(Q12,"NO")+COUNTIF(R12,"NO")=0,"CUMPLE","NO CUMPLE")))))) -> NO CUMPLE | T12: BRANDO CHAMORRO
A13: REHABILITACION | B13: =COUNTIFS(H:H,"FISIOTERAPEUTA",S:S,"CUMPLE") -> 0 | C13: =COUNTIFS(H:H,"FISIOTERAPEUTA") -> 0 | D13: =IFERROR(COUNTIFS(H:H,"FISIOTERAPEUTA",S:S,"CUMPLE")/COUNTIFS(H:H,"FISIOTERAPEUTA"),0) -> 0 | E13: 11 | F13: 46030 | G13: UCI | H13: AUXILIAR | I13: CONTACTO | J13: SI | K13: NO | L13: SI | M13: SI | N13: QUIRURGICO | O13: SI | P13: SI | Q13: SI | R13: SI | S13: =IF(I13="CONTACTO",IF(COUNTIF(J13,"NO")+COUNTIF(K13,"SI")+COUNTIF(L13,"NO")+COUNTIF(M13,"NO")+COUNTIF(R13,"NO")=0,"CUMPLE","NO CUMPLE"),IF(I13="VIA AEREA",IF(COUNTIF(K13,"SI")+COUNTIF(L13,"NO")+(COUNTIF(N13,"ALTA EFICIENCIA")-1)+COUNTIF(R13,"NO")=0,"CUMPLE","NO CUMPLE"),IF(I13="VIA AEREA",IF(COUNTIF(J13,"NO")+COUNTIF(K13,"SI")+COUNTIF(L13,"NO")+(COUNTIF(N13,"ALTA EFICIENCIA")-1)+COUNTIF(R13,"NO")=0,"CUMPLE","NO CUMPLE"),IF(I13="GOTAS",IF(COUNTIF(J13,"NO")+COUNTIF(K13,"SI")+COUNTIF(L13,"NO")+(COUNTIF(N13,"ALTA EFICIENCIA")-1)+COUNTIF(R13,"NO")=0,"CUMPLE","NO CUMPLE"),IF(I13="COHORTIZACIÓN",IF(COUNTIF(J13,"NO")+COUNTIF(K13,"SI")+COUNTIF(L13,"NO")+COUNTIF(M13,"NO")+(COUNTIF(N13,"QUIRURGICO")-1)+COUNTIF(M42,"NA")+COUNTIF(O13,"NO")+COUNTIF(P13,"NO")+COUNTIF(Q13,"NO")+COUNTIF(R13,"NO")=0,"CUMPLE","NO CUMPLE")))))) -> CUMPLE | T13: WILSON RAMIREZ
E14: 12 | F14: 45666 | G14: URGENCIAS | H14: AUXILIAR | I14: VIA AEREA | J14: SI | K14: NO | L14: SI | M14: NA | N14: ALTA EFICIENCIA | O14: NO | P14: NO | Q14: NA | R14: SI | S14: =IF(I14="CONTACTO",IF(COUNTIF(J14,"NO")+COUNTIF(K14,"SI")+COUNTIF(L14,"NO")+COUNTIF(M14,"NO")+COUNTIF(R14,"NO")=0,"CUMPLE","NO CUMPLE"),IF(I14="VIA AEREA",IF(COUNTIF(K14,"SI")+COUNTIF(L14,"NO")+(COUNTIF(N14,"ALTA EFICIENCIA")-1)+COUNTIF(R14,"NO")=0,"CUMPLE","NO CUMPLE"),IF(I14="VIA AEREA",IF(COUNTIF(J14,"NO")+COUNTIF(K14,"SI")+COUNTIF(L14,"NO")+(COUNTIF(N14,"ALTA EFICIENCIA")-1)+COUNTIF(R14,"NO")=0,"CUMPLE","NO CUMPLE"),IF(I14="GOTAS",IF(COUNTIF(J14,"NO")+COUNTIF(K14,"SI")+COUNTIF(L14,"NO")+(COUNTIF(N14,"ALTA EFICIENCIA")-1)+COUNTIF(R14,"NO")=0,"CUMPLE","NO CUMPLE"),IF(I14="COHORTIZACIÓN",IF(COUNTIF(J14,"NO")+COUNTIF(K14,"SI")+COUNTIF(L14,"NO")+COUNTIF(M14,"NO")+(COUNTIF(N14,"QUIRURGICO")-1)+COUNTIF(M43,"NA")+COUNTIF(O14,"NO")+COUNTIF(P14,"NO")+COUNTIF(Q14,"NO")+COUNTIF(R14,"NO")=0,"CUMPLE","NO CUMPLE")))))) -> CUMPLE | T14: DAVID BRAVO
A15: ADHERENCIA POR TIPO DE AISLAMIENTO HOSPITALIZACIÓN | E15: 13 | F15: 46035 | G15: HOSPITALIZACIÓN | H15: AUXILIAR | I15: CONTACTO | J15: SI | K15: NO | L15: SI | M15: SI | N15: QUIRURGICO | O15: SI | P15: SI | Q15: SI | R15: SI | S15: =IF(I15="CONTACTO",IF(COUNTIF(J15,"NO")+COUNTIF(K15,"SI")+COUNTIF(L15,"NO")+COUNTIF(M15,"NO")+COUNTIF(R15,"NO")=0,"CUMPLE","NO CUMPLE"),IF(I15="VIA AEREA",IF(COUNTIF(K15,"SI")+COUNTIF(L15,"NO")+(COUNTIF(N15,"ALTA EFICIENCIA")-1)+COUNTIF(R15,"NO")=0,"CUMPLE","NO CUMPLE"),IF(I15="VIA AEREA",IF(COUNTIF(J15,"NO")+COUNTIF(K15,"SI")+COUNTIF(L15,"NO")+(COUNTIF(N15,"ALTA EFICIENCIA")-1)+COUNTIF(R15,"NO")=0,"CUMPLE","NO CUMPLE"),IF(I15="GOTAS",IF(COUNTIF(J15,"NO")+COUNTIF(K15,"SI")+COUNTIF(L15,"NO")+(COUNTIF(N15,"ALTA EFICIENCIA")-1)+COUNTIF(R15,"NO")=0,"CUMPLE","NO CUMPLE"),IF(I15="COHORTIZACIÓN",IF(COUNTIF(J15,"NO")+COUNTIF(K15,"SI")+COUNTIF(L15,"NO")+COUNTIF(M15,"NO")+(COUNTIF(N15,"QUIRURGICO")-1)+COUNTIF(M44,"NA")+COUNTIF(O15,"NO")+COUNTIF(P15,"NO")+COUNTIF(Q15,"NO")+COUNTIF(R15,"NO")=0,"CUMPLE","NO CUMPLE")))))) -> CUMPLE | T15: VIVIAN ASPRILLA | U15: 815
A16: COHORTIZACIÓN | B16: =COUNTIFS(G:G,"HOSPITALIZACIÓN",I:I,"COHORTIZACIÓN",S:S,"CUMPLE") -> 5 | C16: =COUNTIFS(G:G,"HOSPITALIZACIÓN",I:I,"COHORTIZACIÓN") -> 7 | D16: =IFERROR(COUNTIFS(G:G,"HOSPITALIZACIÓN",I:I,"COHORTIZACIÓN",S:S,"CUMPLE")/COUNTIFS(G:G,"HOSPITALIZACIÓN",I:I,"COHORTIZACIÓN"),0) -> 0.71428571 | E16: 14 | F16: 46036 | G16: HOSPITALIZACIÓN 2 | H16: AUXILIAR | I16: CONTACTO | J16: SI | K16: NO | L16: SI | M16: SI | N16: QUIRURGICO | O16: SI | P16: SI | Q16: SI | R16: SI | S16: =IF(I16="CONTACTO",IF(COUNTIF(J16,"NO")+COUNTIF(K16,"SI")+COUNTIF(L16,"NO")+COUNTIF(M16,"NO")+COUNTIF(R16,"NO")=0,"CUMPLE","NO CUMPLE"),IF(I16="VIA AEREA",IF(COUNTIF(K16,"SI")+COUNTIF(L16,"NO")+(COUNTIF(N16,"ALTA EFICIENCIA")-1)+COUNTIF(R16,"NO")=0,"CUMPLE","NO CUMPLE"),IF(I16="VIA AEREA",IF(COUNTIF(J16,"NO")+COUNTIF(K16,"SI")+COUNTIF(L16,"NO")+(COUNTIF(N16,"ALTA EFICIENCIA")-1)+COUNTIF(R16,"NO")=0,"CUMPLE","NO CUMPLE"),IF(I16="GOTAS",IF(COUNTIF(J16,"NO")+COUNTIF(K16,"SI")+COUNTIF(L16,"NO")+(COUNTIF(N16,"ALTA EFICIENCIA")-1)+COUNTIF(R16,"NO")=0,"CUMPLE","NO CUMPLE"),IF(I16="COHORTIZACIÓN",IF(COUNTIF(J16,"NO")+COUNTIF(K16,"SI")+COUNTIF(L16,"NO")+COUNTIF(M16,"NO")+(COUNTIF(N16,"QUIRURGICO")-1)+COUNTIF(M45,"NA")+COUNTIF(O16,"NO")+COUNTIF(P16,"NO")+COUNTIF(Q16,"NO")+COUNTIF(R16,"NO")=0,"CUMPLE","NO CUMPLE")))))) -> CUMPLE | T16: JANNER CASTAÑO
A17: CONTACTO | B17: =COUNTIFS(G:G,"HOSPITALIZACIÓN",I:I,"CONTACTO",S:S,"CUMPLE") -> 8 | C17: =COUNTIFS(G:G,"HOSPITALIZACIÓN",I:I,"CONTACTO") -> 9 | D17: =IFERROR(COUNTIFS(G:G,"HOSPITALIZACIÓN",I:I,"CONTACTO",S:S,"CUMPLE")/COUNTIFS(G:G,"HOSPITALIZACIÓN",I:I,"CONTACTO"),0) -> 0.88888889 | E17: 15 | F17: 46036 | G17: HOSPITALIZACIÓN | H17: ENFERMERA (O) | I17: CONTACTO | J17: SI | K17: NO | L17: SI | M17: SI | N17: QUIRURGICO | O17: NO | P17: SI | Q17: SI | R17: SI | S17: =IF(I17="CONTACTO",IF(COUNTIF(J17,"NO")+COUNTIF(K17,"SI")+COUNTIF(L17,"NO")+COUNTIF(M17,"NO")+COUNTIF(R17,"NO")=0,"CUMPLE","NO CUMPLE"),IF(I17="VIA AEREA",IF(COUNTIF(K17,"SI")+COUNTIF(L17,"NO")+(COUNTIF(N17,"ALTA EFICIENCIA")-1)+COUNTIF(R17,"NO")=0,"CUMPLE","NO CUMPLE"),IF(I17="VIA AEREA",IF(COUNTIF(J17,"NO")+COUNTIF(K17,"SI")+COUNTIF(L17,"NO")+(COUNTIF(N17,"ALTA EFICIENCIA")-1)+COUNTIF(R17,"NO")=0,"CUMPLE","NO CUMPLE"),IF(I17="GOTAS",IF(COUNTIF(J17,"NO")+COUNTIF(K17,"SI")+COUNTIF(L17,"NO")+(COUNTIF(N17,"ALTA EFICIENCIA")-1)+COUNTIF(R17,"NO")=0,"CUMPLE","NO CUMPLE"),IF(I17="COHORTIZACIÓN",IF(COUNTIF(J17,"NO")+COUNTIF(K17,"SI")+COUNTIF(L17,"NO")+COUNTIF(M17,"NO")+(COUNTIF(N17,"QUIRURGICO")-1)+COUNTIF(M46,"NA")+COUNTIF(O17,"NO")+COUNTIF(P17,"NO")+COUNTIF(Q17,"NO")+COUNTIF(R17,"NO")=0,"CUMPLE","NO CUMPLE")))))) -> CUMPLE | T17: ANGELA VALLEJO
A18: GOTAS | B18: =COUNTIFS(G:G,"HOSPITALIZACIÓN",I:I,"GOTAS",S:S,"CUMPLE") -> 0 | C18: =COUNTIFS(G:G,"HOSPITALIZACIÓN",I:I,"GOTAS") -> 0 | D18: =IFERROR(COUNTIFS(G:G,"HOSPITALIZACIÓN",I:I,"GOTAS",S:S,"CUMPLE")/COUNTIFS(G:G,"HOSPITALIZACIÓN",I:I,"GOTAS"),0) -> 0 | E18: 16 | F18: 46037 | G18: HOSPITALIZACIÓN | H18: AUXILIAR | I18: VIA AEREA | J18: SI | K18: NO | L18: SI | M18: NA | N18: ALTA EFICIENCIA | O18: SI | P18: NO | Q18: NA | R18: SI | S18: =IF(I18="CONTACTO",IF(COUNTIF(J18,"NO")+COUNTIF(K18,"SI")+COUNTIF(L18,"NO")+COUNTIF(M18,"NO")+COUNTIF(R18,"NO")=0,"CUMPLE","NO CUMPLE"),IF(I18="VIA AEREA",IF(COUNTIF(K18,"SI")+COUNTIF(L18,"NO")+(COUNTIF(N18,"ALTA EFICIENCIA")-1)+COUNTIF(R18,"NO")=0,"CUMPLE","NO CUMPLE"),IF(I18="VIA AEREA",IF(COUNTIF(J18,"NO")+COUNTIF(K18,"SI")+COUNTIF(L18,"NO")+(COUNTIF(N18,"ALTA EFICIENCIA")-1)+COUNTIF(R18,"NO")=0,"CUMPLE","NO CUMPLE"),IF(I18="GOTAS",IF(COUNTIF(J18,"NO")+COUNTIF(K18,"SI")+COUNTIF(L18,"NO")+(COUNTIF(N18,"ALTA EFICIENCIA")-1)+COUNTIF(R18,"NO")=0,"CUMPLE","NO CUMPLE"),IF(I18="COHORTIZACIÓN",IF(COUNTIF(J18,"NO")+COUNTIF(K18,"SI")+COUNTIF(L18,"NO")+COUNTIF(M18,"NO")+(COUNTIF(N18,"QUIRURGICO")-1)+COUNTIF(M47,"NA")+COUNTIF(O18,"NO")+COUNTIF(P18,"NO")+COUNTIF(Q18,"NO")+COUNTIF(R18,"NO")=0,"CUMPLE","NO CUMPLE")))))) -> CUMPLE | T18: MARIA TORO
A19: VIA AEREA | B19: =COUNTIFS(G:G,"HOSPITALIZACIÓN",I:I,"VIA AEREA",S:S,"CUMPLE") -> 2 | C19: =COUNTIFS(G:G,"HOSPITALIZACIÓN",I:I,"VIA AEREA") -> 2 | D19: =IFERROR(COUNTIFS(G:G,"HOSPITALIZACIÓN",I:I,"VIA AEREA",S:S,"CUMPLE")/COUNTIFS(G:G,"HOSPITALIZACIÓN",I:I,"VIA AEREA"),0) -> 1 | E19: 17 | F19: 46038 | G19: HOSPITALIZACIÓN | H19: MEDICO | I19: COHORTIZACIÓN | J19: SI | K19: NO | L19: SI | M19: SI | N19: QUIRURGICO | O19: SI | P19: SI | Q19: SI | R19: SI | S19: =IF(I19="CONTACTO",IF(COUNTIF(J19,"NO")+COUNTIF(K19,"SI")+COUNTIF(L19,"NO")+COUNTIF(M19,"NO")+COUNTIF(R19,"NO")=0,"CUMPLE","NO CUMPLE"),IF(I19="VIA AEREA",IF(COUNTIF(K19,"SI")+COUNTIF(L19,"NO")+(COUNTIF(N19,"ALTA EFICIENCIA")-1)+COUNTIF(R19,"NO")=0,"CUMPLE","NO CUMPLE"),IF(I19="VIA AEREA",IF(COUNTIF(J19,"NO")+COUNTIF(K19,"SI")+COUNTIF(L19,"NO")+(COUNTIF(N19,"ALTA EFICIENCIA")-1)+COUNTIF(R19,"NO")=0,"CUMPLE","NO CUMPLE"),IF(I19="GOTAS",IF(COUNTIF(J19,"NO")+COUNTIF(K19,"SI")+COUNTIF(L19,"NO")+(COUNTIF(N19,"ALTA EFICIENCIA")-1)+COUNTIF(R19,"NO")=0,"CUMPLE","NO CUMPLE"),IF(I19="COHORTIZACIÓN",IF(COUNTIF(J19,"NO")+COUNTIF(K19,"SI")+COUNTIF(L19,"NO")+COUNTIF(M19,"NO")+(COUNTIF(N19,"QUIRURGICO")-1)+COUNTIF(M48,"NA")+COUNTIF(O19,"NO")+COUNTIF(P19,"NO")+COUNTIF(Q19,"NO")+COUNTIF(R19,"NO")=0,"CUMPLE","NO CUMPLE")))))) -> CUMPLE | T19: LISA LONDOÑO
E20: 18 | F20: 46041 | G20: HOSPITALIZACIÓN | H20: MEDICO | I20: COHORTIZACIÓN | J20: SI | K20: NO | L20: SI | M20: SI | N20: QUIRURGICO | O20: SI | P20: SI | Q20: SI | R20: SI | S20: =IF(I20="CONTACTO",IF(COUNTIF(J20,"NO")+COUNTIF(K20,"SI")+COUNTIF(L20,"NO")+COUNTIF(M20,"NO")+COUNTIF(R20,"NO")=0,"CUMPLE","NO CUMPLE"),IF(I20="VIA AEREA",IF(COUNTIF(K20,"SI")+COUNTIF(L20,"NO")+(COUNTIF(N20,"ALTA EFICIENCIA")-1)+COUNTIF(R20,"NO")=0,"CUMPLE","NO CUMPLE"),IF(I20="VIA AEREA",IF(COUNTIF(J20,"NO")+COUNTIF(K20,"SI")+COUNTIF(L20,"NO")+(COUNTIF(N20,"ALTA EFICIENCIA")-1)+COUNTIF(R20,"NO")=0,"CUMPLE","NO CUMPLE"),IF(I20="GOTAS",IF(COUNTIF(J20,"NO")+COUNTIF(K20,"SI")+COUNTIF(L20,"NO")+(COUNTIF(N20,"ALTA EFICIENCIA")-1)+COUNTIF(R20,"NO")=0,"CUMPLE","NO CUMPLE"),IF(I20="COHORTIZACIÓN",IF(COUNTIF(J20,"NO")+COUNTIF(K20,"SI")+COUNTIF(L20,"NO")+COUNTIF(M20,"NO")+(COUNTIF(N20,"QUIRURGICO")-1)+COUNTIF(M49,"NA")+COUNTIF(O20,"NO")+COUNTIF(P20,"NO")+COUNTIF(Q20,"NO")+COUNTIF(R20,"NO")=0,"CUMPLE","NO CUMPLE")))))) -> CUMPLE | T20: LAWRENCE DOMINGUEZ
A21: ADHERENCIA POR TIPO DE PROFESIÓN HOSPITALIZACIÓN | E21: 19 | F21: 45676 | G21: HOSPITALIZACIÓN | H21: ENFERMERA (O) | I21: CONTACTO | J21: SI | K21: NO | L21: SI | M21: SI | N21: QUIRURGICO | O21: SI | P21: SI | Q21: SI | R21: SI | S21: =IF(I21="CONTACTO",IF(COUNTIF(J21,"NO")+COUNTIF(K21,"SI")+COUNTIF(L21,"NO")+COUNTIF(M21,"NO")+COUNTIF(R21,"NO")=0,"CUMPLE","NO CUMPLE"),IF(I21="VIA AEREA",IF(COUNTIF(K21,"SI")+COUNTIF(L21,"NO")+(COUNTIF(N21,"ALTA EFICIENCIA")-1)+COUNTIF(R21,"NO")=0,"CUMPLE","NO CUMPLE"),IF(I21="VIA AEREA",IF(COUNTIF(J21,"NO")+COUNTIF(K21,"SI")+COUNTIF(L21,"NO")+(COUNTIF(N21,"ALTA EFICIENCIA")-1)+COUNTIF(R21,"NO")=0,"CUMPLE","NO CUMPLE"),IF(I21="GOTAS",IF(COUNTIF(J21,"NO")+COUNTIF(K21,"SI")+COUNTIF(L21,"NO")+(COUNTIF(N21,"ALTA EFICIENCIA")-1)+COUNTIF(R21,"NO")=0,"CUMPLE","NO CUMPLE"),IF(I21="COHORTIZACIÓN",IF(COUNTIF(J21,"NO")+COUNTIF(K21,"SI")+COUNTIF(L21,"NO")+COUNTIF(M21,"NO")+(COUNTIF(N21,"QUIRURGICO")-1)+COUNTIF(M50,"NA")+COUNTIF(O21,"NO")+COUNTIF(P21,"NO")+COUNTIF(Q21,"NO")+COUNTIF(R21,"NO")=0,"CUMPLE","NO CUMPLE")))))) -> CUMPLE | T21: GUSTAVO VASQUEZ
A22: AUXILIAR | B22: =COUNTIFS(G:G,"HOSPITALIZACIÓN",H:H,"AUXILIAR",S:S,"CUMPLE") -> 7 | C22: =COUNTIFS(G:G,"HOSPITALIZACIÓN",H:H,"AUXILIAR") -> 8 | D22: =IFERROR(COUNTIFS(G:G,"HOSPITALIZACIÓN",H:H,"AUXILIAR",S:S,"CUMPLE")/COUNTIFS(G:G,"HOSPITALIZACIÓN",H:H,"AUXILIAR"),0) -> 0.875 | E22: 20 | F22: 19/01/1016 | G22: URGENCIAS | H22: ENFERMERA (O) | I22: CONTACTO | J22: SI | K22: NO | L22: SI | M22: SI | N22: QUIRURGICO | O22: SI | P22: SI | Q22: SI | R22: SI | S22: =IF(I22="CONTACTO",IF(COUNTIF(J22,"NO")+COUNTIF(K22,"SI")+COUNTIF(L22,"NO")+COUNTIF(M22,"NO")+COUNTIF(R22,"NO")=0,"CUMPLE","NO CUMPLE"),IF(I22="VIA AEREA",IF(COUNTIF(K22,"SI")+COUNTIF(L22,"NO")+(COUNTIF(N22,"ALTA EFICIENCIA")-1)+COUNTIF(R22,"NO")=0,"CUMPLE","NO CUMPLE"),IF(I22="VIA AEREA",IF(COUNTIF(J22,"NO")+COUNTIF(K22,"SI")+COUNTIF(L22,"NO")+(COUNTIF(N22,"ALTA EFICIENCIA")-1)+COUNTIF(R22,"NO")=0,"CUMPLE","NO CUMPLE"),IF(I22="GOTAS",IF(COUNTIF(J22,"NO")+COUNTIF(K22,"SI")+COUNTIF(L22,"NO")+(COUNTIF(N22,"ALTA EFICIENCIA")-1)+COUNTIF(R22,"NO")=0,"CUMPLE","NO CUMPLE"),IF(I22="COHORTIZACIÓN",IF(COUNTIF(J22,"NO")+COUNTIF(K22,"SI")+COUNTIF(L22,"NO")+COUNTIF(M22,"NO")+(COUNTIF(N22,"QUIRURGICO")-1)+COUNTIF(M51,"NA")+COUNTIF(O22,"NO")+COUNTIF(P22,"NO")+COUNTIF(Q22,"NO")+COUNTIF(R22,"NO")=0,"CUMPLE","NO CUMPLE")))))) -> CUMPLE | T22: EVELYN OBREGON
A23: ENFERMERA | B23: =COUNTIFS(G:G,"HOSPITALIZACIÓN",H:H,"ENFERMERA",S:S,"CUMPLE") -> 0 | C23: =COUNTIFS(G:G,"HOSPITALIZACIÓN",H:H,"ENFERMERA") -> 0 | D23: =IFERROR(COUNTIFS(G:G,"HOSPITALIZACIÓN",H:H,"ENFERMERA",S:S,"CUMPLE")/COUNTIFS(G:G,"HOSPITALIZACIÓN",H:H,"ENFERMERA"),0) -> 0 | E23: 21 | F23: 46042 | G23: URGENCIAS | H23: AUXILIAR | I23: CONTACTO | J23: SI | K23: NO | L23: SI | M23: SI | N23: QUIRURGICO | O23: NO | P23: NO | Q23: NO | R23: NO | S23: =IF(I23="CONTACTO",IF(COUNTIF(J23,"NO")+COUNTIF(K23,"SI")+COUNTIF(L23,"NO")+COUNTIF(M23,"NO")+COUNTIF(R23,"NO")=0,"CUMPLE","NO CUMPLE"),IF(I23="VIA AEREA",IF(COUNTIF(K23,"SI")+COUNTIF(L23,"NO")+(COUNTIF(N23,"ALTA EFICIENCIA")-1)+COUNTIF(R23,"NO")=0,"CUMPLE","NO CUMPLE"),IF(I23="VIA AEREA",IF(COUNTIF(J23,"NO")+COUNTIF(K23,"SI")+COUNTIF(L23,"NO")+(COUNTIF(N23,"ALTA EFICIENCIA")-1)+COUNTIF(R23,"NO")=0,"CUMPLE","NO CUMPLE"),IF(I23="GOTAS",IF(COUNTIF(J23,"NO")+COUNTIF(K23,"SI")+COUNTIF(L23,"NO")+(COUNTIF(N23,"ALTA EFICIENCIA")-1)+COUNTIF(R23,"NO")=0,"CUMPLE","NO CUMPLE"),IF(I23="COHORTIZACIÓN",IF(COUNTIF(J23,"NO")+COUNTIF(K23,"SI")+COUNTIF(L23,"NO")+COUNTIF(M23,"NO")+(COUNTIF(N23,"QUIRURGICO")-1)+COUNTIF(M52,"NA")+COUNTIF(O23,"NO")+COUNTIF(P23,"NO")+COUNTIF(Q23,"NO")+COUNTIF(R23,"NO")=0,"CUMPLE","NO CUMPLE")))))) -> NO CUMPLE | T23: MARIANA LOPEZ
A24: REHABILITACION | B24: =COUNTIFS(G:G,"HOSPITALIZACIÓN",H:H,"FISIOTERAPEUTA",S:S,"CUMPLE") -> 0 | C24: =COUNTIFS(G:G,"HOSPITALIZACIÓN",H:H,"FISIOTERAPEUTA") -> 0 | D24: =IFERROR(COUNTIFS(G:G,"HOSPITALIZACIÓN",H:H,"FISIOTERAPEUTA",S:S,"CUMPLE")/COUNTIFS(G:G,"HOSPITALIZACIÓN",H:H,"FISIOTERAPEUTA"),0) -> 0 | E24: 22 | F24: 46042 | G24: HOSPITALIZACIÓN | H24: MEDICO | I24: COHORTIZACIÓN | J24: SI | K24: NO | L24: SI | M24: SI | N24: QUIRURGICO | O24: SI | P24: SI | Q24: SI | R24: SI | S24: =IF(I24="CONTACTO",IF(COUNTIF(J24,"NO")+COUNTIF(K24,"SI")+COUNTIF(L24,"NO")+COUNTIF(M24,"NO")+COUNTIF(R24,"NO")=0,"CUMPLE","NO CUMPLE"),IF(I24="VIA AEREA",IF(COUNTIF(K24,"SI")+COUNTIF(L24,"NO")+(COUNTIF(N24,"ALTA EFICIENCIA")-1)+COUNTIF(R24,"NO")=0,"CUMPLE","NO CUMPLE"),IF(I24="VIA AEREA",IF(COUNTIF(J24,"NO")+COUNTIF(K24,"SI")+COUNTIF(L24,"NO")+(COUNTIF(N24,"ALTA EFICIENCIA")-1)+COUNTIF(R24,"NO")=0,"CUMPLE","NO CUMPLE"),IF(I24="GOTAS",IF(COUNTIF(J24,"NO")+COUNTIF(K24,"SI")+COUNTIF(L24,"NO")+(COUNTIF(N24,"ALTA EFICIENCIA")-1)+COUNTIF(R24,"NO")=0,"CUMPLE","NO CUMPLE"),IF(I24="COHORTIZACIÓN",IF(COUNTIF(J24,"NO")+COUNTIF(K24,"SI")+COUNTIF(L24,"NO")+COUNTIF(M24,"NO")+(COUNTIF(N24,"QUIRURGICO")-1)+COUNTIF(M53,"NA")+COUNTIF(O24,"NO")+COUNTIF(P24,"NO")+COUNTIF(Q24,"NO")+COUNTIF(R24,"NO")=0,"CUMPLE","NO CUMPLE")))))) -> CUMPLE | T24: ANA MARIA VARELA
A25: MEDICO | B25: =COUNTIFS(G:G,"HOSPITALIZACIÓN",H:H,"MEDICO",S:S,"CUMPLE") -> 4 | C25: =COUNTIFS(G:G,"HOSPITALIZACIÓN",H:H,"MEDICO") -> 5 | D25: =IFERROR(COUNTIFS(G:G,"HOSPITALIZACIÓN",H:H,"MEDICO",S:S,"CUMPLE")/COUNTIFS(G:G,"HOSPITALIZACIÓN",H:H,"MEDICO"),0) -> 0.8 | E25: 23 | F25: 46042 | G25: HOSPITALIZACIÓN | H25: ENFERMERA (O) | I25: COHORTIZACIÓN | J25: SI | K25: NO | L25: SI | M25: SI | N25: QUIRURGICO | O25: NO | P25: NO | Q25: NO | R25: NO | S25: =IF(I25="CONTACTO",IF(COUNTIF(J25,"NO")+COUNTIF(K25,"SI")+COUNTIF(L25,"NO")+COUNTIF(M25,"NO")+COUNTIF(R25,"NO")=0,"CUMPLE","NO CUMPLE"),IF(I25="VIA AEREA",IF(COUNTIF(K25,"SI")+COUNTIF(L25,"NO")+(COUNTIF(N25,"ALTA EFICIENCIA")-1)+COUNTIF(R25,"NO")=0,"CUMPLE","NO CUMPLE"),IF(I25="VIA AEREA",IF(COUNTIF(J25,"NO")+COUNTIF(K25,"SI")+COUNTIF(L25,"NO")+(COUNTIF(N25,"ALTA EFICIENCIA")-1)+COUNTIF(R25,"NO")=0,"CUMPLE","NO CUMPLE"),IF(I25="GOTAS",IF(COUNTIF(J25,"NO")+COUNTIF(K25,"SI")+COUNTIF(L25,"NO")+(COUNTIF(N25,"ALTA EFICIENCIA")-1)+COUNTIF(R25,"NO")=0,"CUMPLE","NO CUMPLE"),IF(I25="COHORTIZACIÓN",IF(COUNTIF(J25,"NO")+COUNTIF(K25,"SI")+COUNTIF(L25,"NO")+COUNTIF(M25,"NO")+(COUNTIF(N25,"QUIRURGICO")-1)+COUNTIF(M54,"NA")+COUNTIF(O25,"NO")+COUNTIF(P25,"NO")+COUNTIF(Q25,"NO")+COUNTIF(R25,"NO")=0,"CUMPLE","NO CUMPLE")))))) -> NO CUMPLE | T25: STEFFANNI ORTIZ
A26: MEDICO ESP | E26: 24 | F26: 46042 | G26: URGENCIAS | H26: NUTRICIONISTA | I26: CONTACTO | J26: SI | K26: NO | L26: SI | M26: SI | N26: QUIRURGICO | O26: SI | P26: SI | Q26: SI | R26: SI | S26: =IF(I26="CONTACTO",IF(COUNTIF(J26,"NO")+COUNTIF(K26,"SI")+COUNTIF(L26,"NO")+COUNTIF(M26,"NO")+COUNTIF(R26,"NO")=0,"CUMPLE","NO CUMPLE"),IF(I26="VIA AEREA",IF(COUNTIF(K26,"SI")+COUNTIF(L26,"NO")+(COUNTIF(N26,"ALTA EFICIENCIA")-1)+COUNTIF(R26,"NO")=0,"CUMPLE","NO CUMPLE"),IF(I26="VIA AEREA",IF(COUNTIF(J26,"NO")+COUNTIF(K26,"SI")+COUNTIF(L26,"NO")+(COUNTIF(N26,"ALTA EFICIENCIA")-1)+COUNTIF(R26,"NO")=0,"CUMPLE","NO CUMPLE"),IF(I26="GOTAS",IF(COUNTIF(J26,"NO")+COUNTIF(K26,"SI")+COUNTIF(L26,"NO")+(COUNTIF(N26,"ALTA EFICIENCIA")-1)+COUNTIF(R26,"NO")=0,"CUMPLE","NO CUMPLE"),IF(I26="COHORTIZACIÓN",IF(COUNTIF(J26,"NO")+COUNTIF(K26,"SI")+COUNTIF(L26,"NO")+COUNTIF(M26,"NO")+(COUNTIF(N26,"QUIRURGICO")-1)+COUNTIF(M55,"NA")+COUNTIF(O26,"NO")+COUNTIF(P26,"NO")+COUNTIF(Q26,"NO")+COUNTIF(R26,"NO")=0,"CUMPLE","NO CUMPLE")))))) -> CUMPLE | T26: LAURA CABAL
A27: ADHERENCIA POR TIPO DE AISLAMIENTO UCI | E27: 25 | F27: 46042 | G27: URGENCIAS | H27: MEDICO ESP | I27: CONTACTO | J27: SI | K27: NO | L27: SI | M27: SI | N27: NO | O27: SI | P27: SI | Q27: NO | R27: NO | S27: =IF(I27="CONTACTO",IF(COUNTIF(J27,"NO")+COUNTIF(K27,"SI")+COUNTIF(L27,"NO")+COUNTIF(M27,"NO")+COUNTIF(R27,"NO")=0,"CUMPLE","NO CUMPLE"),IF(I27="VIA AEREA",IF(COUNTIF(K27,"SI")+COUNTIF(L27,"NO")+(COUNTIF(N27,"ALTA EFICIENCIA")-1)+COUNTIF(R27,"NO")=0,"CUMPLE","NO CUMPLE"),IF(I27="VIA AEREA",IF(COUNTIF(J27,"NO")+COUNTIF(K27,"SI")+COUNTIF(L27,"NO")+(COUNTIF(N27,"ALTA EFICIENCIA")-1)+COUNTIF(R27,"NO")=0,"CUMPLE","NO CUMPLE"),IF(I27="GOTAS",IF(COUNTIF(J27,"NO")+COUNTIF(K27,"SI")+COUNTIF(L27,"NO")+(COUNTIF(N27,"ALTA EFICIENCIA")-1)+COUNTIF(R27,"NO")=0,"CUMPLE","NO CUMPLE"),IF(I27="COHORTIZACIÓN",IF(COUNTIF(J27,"NO")+COUNTIF(K27,"SI")+COUNTIF(L27,"NO")+COUNTIF(M27,"NO")+(COUNTIF(N27,"QUIRURGICO")-1)+COUNTIF(M56,"NA")+COUNTIF(O27,"NO")+COUNTIF(P27,"NO")+COUNTIF(Q27,"NO")+COUNTIF(R27,"NO")=0,"CUMPLE","NO CUMPLE")))))) -> NO CUMPLE | T27: ANDRES TAFUR
A28: COHORTIZACIÓN | B28: =COUNTIFS(G:G,"UCI",I:I,"COHORTIZACIÓN",S:S,"CUMPLE") -> 0 | C28: =COUNTIFS(G:G,"UCI",I:I,"COHORTIZACIÓN") -> 1 | D28: =IFERROR(COUNTIFS(G:G,"UCI",I:I,"COHORTIZACIÓN",S:S,"CUMPLE")/COUNTIFS(G:G,"UCI",I:I,"COHORTIZACIÓN"),0) -> 0 | E28: 26 | F28: 46042 | G28: URGENCIAS | H28: MEDICO | I28: VIA AEREA | J28: SI | K28: NO | L28: SI | M28: SI | N28: ALTA EFICIENCIA | O28: SI | P28: SI | Q28: SI | R28: SI | S28: =IF(I28="CONTACTO",IF(COUNTIF(J28,"NO")+COUNTIF(K28,"SI")+COUNTIF(L28,"NO")+COUNTIF(M28,"NO")+COUNTIF(R28,"NO")=0,"CUMPLE","NO CUMPLE"),IF(I28="VIA AEREA",IF(COUNTIF(K28,"SI")+COUNTIF(L28,"NO")+(COUNTIF(N28,"ALTA EFICIENCIA")-1)+COUNTIF(R28,"NO")=0,"CUMPLE","NO CUMPLE"),IF(I28="VIA AEREA",IF(COUNTIF(J28,"NO")+COUNTIF(K28,"SI")+COUNTIF(L28,"NO")+(COUNTIF(N28,"ALTA EFICIENCIA")-1)+COUNTIF(R28,"NO")=0,"CUMPLE","NO CUMPLE"),IF(I28="GOTAS",IF(COUNTIF(J28,"NO")+COUNTIF(K28,"SI")+COUNTIF(L28,"NO")+(COUNTIF(N28,"ALTA EFICIENCIA")-1)+COUNTIF(R28,"NO")=0,"CUMPLE","NO CUMPLE"),IF(I28="COHORTIZACIÓN",IF(COUNTIF(J28,"NO")+COUNTIF(K28,"SI")+COUNTIF(L28,"NO")+COUNTIF(M28,"NO")+(COUNTIF(N28,"QUIRURGICO")-1)+COUNTIF(M57,"NA")+COUNTIF(O28,"NO")+COUNTIF(P28,"NO")+COUNTIF(Q28,"NO")+COUNTIF(R28,"NO")=0,"CUMPLE","NO CUMPLE")))))) -> CUMPLE | T28: JULIANA CEDEÑO
A29: CONTACTO | B29: =COUNTIFS(G:G,"UCI",I:I,"CONTACTO",S:S,"CUMPLE") -> 6 | C29: =COUNTIFS(G:G,"UCI",I:I,"CONTACTO") -> 6 | D29: =IFERROR(COUNTIFS(G:G,"UCI",I:I,"CONTACTO",S:S,"CUMPLE")/COUNTIFS(G:G,"UCI",I:I,"CONTACTO"),0) -> 1 | E29: 27 | F29: 46042 | G29: URGENCIAS | H29: AUXILIAR | I29: CONTACTO | J29: SI | K29: NO | L29: SI | M29: SI | N29: QUIRURGICO | O29: SI | P29: SI | Q29: SI | R29: SI | S29: =IF(I29="CONTACTO",IF(COUNTIF(J29,"NO")+COUNTIF(K29,"SI")+COUNTIF(L29,"NO")+COUNTIF(M29,"NO")+COUNTIF(R29,"NO")=0,"CUMPLE","NO CUMPLE"),IF(I29="VIA AEREA",IF(COUNTIF(K29,"SI")+COUNTIF(L29,"NO")+(COUNTIF(N29,"ALTA EFICIENCIA")-1)+COUNTIF(R29,"NO")=0,"CUMPLE","NO CUMPLE"),IF(I29="VIA AEREA",IF(COUNTIF(J29,"NO")+COUNTIF(K29,"SI")+COUNTIF(L29,"NO")+(COUNTIF(N29,"ALTA EFICIENCIA")-1)+COUNTIF(R29,"NO")=0,"CUMPLE","NO CUMPLE"),IF(I29="GOTAS",IF(COUNTIF(J29,"NO")+COUNTIF(K29,"SI")+COUNTIF(L29,"NO")+(COUNTIF(N29,"ALTA EFICIENCIA")-1)+COUNTIF(R29,"NO")=0,"CUMPLE","NO CUMPLE"),IF(I29="COHORTIZACIÓN",IF(COUNTIF(J29,"NO")+COUNTIF(K29,"SI")+COUNTIF(L29,"NO")+COUNTIF(M29,"NO")+(COUNTIF(N29,"QUIRURGICO")-1)+COUNTIF(M58,"NA")+COUNTIF(O29,"NO")+COUNTIF(P29,"NO")+COUNTIF(Q29,"NO")+COUNTIF(R29,"NO")=0,"CUMPLE","NO CUMPLE")))))) -> CUMPLE | T29: DAVID BRAVO
A30: GOTAS | B30: =COUNTIFS(G:G,"UCI",I:I,"GOTAS",S:S,"CUMPLE") -> 0 | C30: =COUNTIFS(G:G,"UCI",I:I,"GOTAS") -> 0 | D30: =IFERROR(COUNTIFS(G:G,"UCI",I:I,"GOTAS",S:S,"CUMPLE")/COUNTIFS(G:G,"UCI",I:I,"GOTAS"),0) -> 0 | E30: 28 | F30: 46042 | G30: URGENCIAS | H30: ENFERMERA (O) | I30: CONTACTO | J30: SI | K30: NO | L30: SI | M30: SI | N30: QUIRURGICO | O30: SI | P30: SI | Q30: SI | R30: SI | S30: =IF(I30="CONTACTO",IF(COUNTIF(J30,"NO")+COUNTIF(K30,"SI")+COUNTIF(L30,"NO")+COUNTIF(M30,"NO")+COUNTIF(R30,"NO")=0,"CUMPLE","NO CUMPLE"),IF(I30="VIA AEREA",IF(COUNTIF(K30,"SI")+COUNTIF(L30,"NO")+(COUNTIF(N30,"ALTA EFICIENCIA")-1)+COUNTIF(R30,"NO")=0,"CUMPLE","NO CUMPLE"),IF(I30="VIA AEREA",IF(COUNTIF(J30,"NO")+COUNTIF(K30,"SI")+COUNTIF(L30,"NO")+(COUNTIF(N30,"ALTA EFICIENCIA")-1)+COUNTIF(R30,"NO")=0,"CUMPLE","NO CUMPLE"),IF(I30="GOTAS",IF(COUNTIF(J30,"NO")+COUNTIF(K30,"SI")+COUNTIF(L30,"NO")+(COUNTIF(N30,"ALTA EFICIENCIA")-1)+COUNTIF(R30,"NO")=0,"CUMPLE","NO CUMPLE"),IF(I30="COHORTIZACIÓN",IF(COUNTIF(J30,"NO")+COUNTIF(K30,"SI")+COUNTIF(L30,"NO")+COUNTIF(M30,"NO")+(COUNTIF(N30,"QUIRURGICO")-1)+COUNTIF(M59,"NA")+COUNTIF(O30,"NO")+COUNTIF(P30,"NO")+COUNTIF(Q30,"NO")+COUNTIF(R30,"NO")=0,"CUMPLE","NO CUMPLE")))))) -> CUMPLE | T30: YULIZA BEJARANO
A31: VIA AEREA | B31: =COUNTIFS(G:G,"UCI",I:I,"VIA AEREA",S:S,"CUMPLE") -> 2 | C31: =COUNTIFS(G:G,"UCI",I:I,"VIA AEREA") -> 2 | D31: =IFERROR(COUNTIFS(G:G,"UCI",I:I,"VIA AEREA",S:S,"CUMPLE")/COUNTIFS(G:G,"UCI",I:I,"VIA AEREA"),0) -> 1 | E31: 29 | F31: 46043 | G31: UCI | H31: AUXILIAR | I31: CONTACTO | J31: SI | K31: NO | L31: SI | M31: SI | N31: QUIRURGICO | O31: SI | P31: SI | Q31: SI | R31: SI | S31: =IF(I31="CONTACTO",IF(COUNTIF(J31,"NO")+COUNTIF(K31,"SI")+COUNTIF(L31,"NO")+COUNTIF(M31,"NO")+COUNTIF(R31,"NO")=0,"CUMPLE","NO CUMPLE"),IF(I31="VIA AEREA",IF(COUNTIF(K31,"SI")+COUNTIF(L31,"NO")+(COUNTIF(N31,"ALTA EFICIENCIA")-1)+COUNTIF(R31,"NO")=0,"CUMPLE","NO CUMPLE"),IF(I31="VIA AEREA",IF(COUNTIF(J31,"NO")+COUNTIF(K31,"SI")+COUNTIF(L31,"NO")+(COUNTIF(N31,"ALTA EFICIENCIA")-1)+COUNTIF(R31,"NO")=0,"CUMPLE","NO CUMPLE"),IF(I31="GOTAS",IF(COUNTIF(J31,"NO")+COUNTIF(K31,"SI")+COUNTIF(L31,"NO")+(COUNTIF(N31,"ALTA EFICIENCIA")-1)+COUNTIF(R31,"NO")=0,"CUMPLE","NO CUMPLE"),IF(I31="COHORTIZACIÓN",IF(COUNTIF(J31,"NO")+COUNTIF(K31,"SI")+COUNTIF(L31,"NO")+COUNTIF(M31,"NO")+(COUNTIF(N31,"QUIRURGICO")-1)+COUNTIF(M60,"NA")+COUNTIF(O31,"NO")+COUNTIF(P31,"NO")+COUNTIF(Q31,"NO")+COUNTIF(R31,"NO")=0,"CUMPLE","NO CUMPLE")))))) -> CUMPLE | T31: DILAN MONTOYA
E32: 30 | F32: 46044 | G32: UCI | H32: AUXILIAR | I32: CONTACTO | J32: SI | K32: NO | L32: SI | M32: SI | N32: QUIRURGICO | O32: SI | P32: SI | Q32: SI | R32: SI | S32: =IF(I32="CONTACTO",IF(COUNTIF(J32,"NO")+COUNTIF(K32,"SI")+COUNTIF(L32,"NO")+COUNTIF(M32,"NO")+COUNTIF(R32,"NO")=0,"CUMPLE","NO CUMPLE"),IF(I32="VIA AEREA",IF(COUNTIF(K32,"SI")+COUNTIF(L32,"NO")+(COUNTIF(N32,"ALTA EFICIENCIA")-1)+COUNTIF(R32,"NO")=0,"CUMPLE","NO CUMPLE"),IF(I32="VIA AEREA",IF(COUNTIF(J32,"NO")+COUNTIF(K32,"SI")+COUNTIF(L32,"NO")+(COUNTIF(N32,"ALTA EFICIENCIA")-1)+COUNTIF(R32,"NO")=0,"CUMPLE","NO CUMPLE"),IF(I32="GOTAS",IF(COUNTIF(J32,"NO")+COUNTIF(K32,"SI")+COUNTIF(L32,"NO")+(COUNTIF(N32,"ALTA EFICIENCIA")-1)+COUNTIF(R32,"NO")=0,"CUMPLE","NO CUMPLE"),IF(I32="COHORTIZACIÓN",IF(COUNTIF(J32,"NO")+COUNTIF(K32,"SI")+COUNTIF(L32,"NO")+COUNTIF(M32,"NO")+(COUNTIF(N32,"QUIRURGICO")-1)+COUNTIF(M61,"NA")+COUNTIF(O32,"NO")+COUNTIF(P32,"NO")+COUNTIF(Q32,"NO")+COUNTIF(R32,"NO")=0,"CUMPLE","NO CUMPLE")))))) -> CUMPLE | T32: ROSA APARICIO
A33: ADHERENCIA POR TIPO DE PROFESIÓN UCI | E33: 31 | F33: 46044 | G33: HOSPITALIZACIÓN | H33: MEDICO ESP | I33: CONTACTO | J33: SI | K33: NO | L33: SI | M33: SI | N33: ALTA EFICIENCIA | O33: NO | P33: SI | Q33: SI | R33: SI | S33: =IF(I33="CONTACTO",IF(COUNTIF(J33,"NO")+COUNTIF(K33,"SI")+COUNTIF(L33,"NO")+COUNTIF(M33,"NO")+COUNTIF(R33,"NO")=0,"CUMPLE","NO CUMPLE"),IF(I33="VIA AEREA",IF(COUNTIF(K33,"SI")+COUNTIF(L33,"NO")+(COUNTIF(N33,"ALTA EFICIENCIA")-1)+COUNTIF(R33,"NO")=0,"CUMPLE","NO CUMPLE"),IF(I33="VIA AEREA",IF(COUNTIF(J33,"NO")+COUNTIF(K33,"SI")+COUNTIF(L33,"NO")+(COUNTIF(N33,"ALTA EFICIENCIA")-1)+COUNTIF(R33,"NO")=0,"CUMPLE","NO CUMPLE"),IF(I33="GOTAS",IF(COUNTIF(J33,"NO")+COUNTIF(K33,"SI")+COUNTIF(L33,"NO")+(COUNTIF(N33,"ALTA EFICIENCIA")-1)+COUNTIF(R33,"NO")=0,"CUMPLE","NO CUMPLE"),IF(I33="COHORTIZACIÓN",IF(COUNTIF(J33,"NO")+COUNTIF(K33,"SI")+COUNTIF(L33,"NO")+COUNTIF(M33,"NO")+(COUNTIF(N33,"QUIRURGICO")-1)+COUNTIF(M62,"NA")+COUNTIF(O33,"NO")+COUNTIF(P33,"NO")+COUNTIF(Q33,"NO")+COUNTIF(R33,"NO")=0,"CUMPLE","NO CUMPLE")))))) -> CUMPLE | T33: JOSE PIMENTEL
A34: AUXILIAR | B34: =COUNTIFS(G:G,"UCI",H:H,"AUXILIAR",S:S,"CUMPLE") -> 6 | C34: =COUNTIFS(G:G,"UCI",H:H,"AUXILIAR") -> 7 | D34: =IFERROR(COUNTIFS(G:G,"UCI",H:H,"AUXILIAR",S:S,"CUMPLE")/COUNTIFS(G:G,"UCI",H:H,"AUXILIAR"),0) -> 0.85714286 | E34: 32 | F34: 46044 | G34: UCI | H34: MEDICO | I34: VIA AEREA | J34: SI | K34: NO | L34: SI | M34: SI | N34: ALTA EFICIENCIA | O34: SI | P34: SI | Q34: SI | R34: SI | S34: =IF(I34="CONTACTO",IF(COUNTIF(J34,"NO")+COUNTIF(K34,"SI")+COUNTIF(L34,"NO")+COUNTIF(M34,"NO")+COUNTIF(R34,"NO")=0,"CUMPLE","NO CUMPLE"),IF(I34="VIA AEREA",IF(COUNTIF(K34,"SI")+COUNTIF(L34,"NO")+(COUNTIF(N34,"ALTA EFICIENCIA")-1)+COUNTIF(R34,"NO")=0,"CUMPLE","NO CUMPLE"),IF(I34="VIA AEREA",IF(COUNTIF(J34,"NO")+COUNTIF(K34,"SI")+COUNTIF(L34,"NO")+(COUNTIF(N34,"ALTA EFICIENCIA")-1)+COUNTIF(R34,"NO")=0,"CUMPLE","NO CUMPLE"),IF(I34="GOTAS",IF(COUNTIF(J34,"NO")+COUNTIF(K34,"SI")+COUNTIF(L34,"NO")+(COUNTIF(N34,"ALTA EFICIENCIA")-1)+COUNTIF(R34,"NO")=0,"CUMPLE","NO CUMPLE"),IF(I34="COHORTIZACIÓN",IF(COUNTIF(J34,"NO")+COUNTIF(K34,"SI")+COUNTIF(L34,"NO")+COUNTIF(M34,"NO")+(COUNTIF(N34,"QUIRURGICO")-1)+COUNTIF(M63,"NA")+COUNTIF(O34,"NO")+COUNTIF(P34,"NO")+COUNTIF(Q34,"NO")+COUNTIF(R34,"NO")=0,"CUMPLE","NO CUMPLE")))))) -> CUMPLE | T34: GUSTAVO CANIZALES
A35: ENFERMERA | B35: =COUNTIFS(G:G,"UCI",H:H,"ENFERMERA",S:S,"CUMPLE") -> 0 | C35: =COUNTIFS(G:G,"UCI",H:H,"ENFERMERA") -> 0 | D35: =IFERROR(COUNTIFS(G:G,"UCI",H:H,"ENFERMERA",S:S,"CUMPLE")/COUNTIFS(G:G,"UCI",H:H,"ENFERMERA"),0) -> 0 | E35: 33 | F35: 46045 | G35: URGENCIAS | H35: AUXILIAR | I35: VIA AEREA | J35: SI | K35: NO | L35: SI | M35: NA | N35: ALTA EFICIENCIA | O35: SI | P35: SI | Q35: NA | R35: SI | S35: =IF(I35="CONTACTO",IF(COUNTIF(J35,"NO")+COUNTIF(K35,"SI")+COUNTIF(L35,"NO")+COUNTIF(M35,"NO")+COUNTIF(R35,"NO")=0,"CUMPLE","NO CUMPLE"),IF(I35="VIA AEREA",IF(COUNTIF(K35,"SI")+COUNTIF(L35,"NO")+(COUNTIF(N35,"ALTA EFICIENCIA")-1)+COUNTIF(R35,"NO")=0,"CUMPLE","NO CUMPLE"),IF(I35="VIA AEREA",IF(COUNTIF(J35,"NO")+COUNTIF(K35,"SI")+COUNTIF(L35,"NO")+(COUNTIF(N35,"ALTA EFICIENCIA")-1)+COUNTIF(R35,"NO")=0,"CUMPLE","NO CUMPLE"),IF(I35="GOTAS",IF(COUNTIF(J35,"NO")+COUNTIF(K35,"SI")+COUNTIF(L35,"NO")+(COUNTIF(N35,"ALTA EFICIENCIA")-1)+COUNTIF(R35,"NO")=0,"CUMPLE","NO CUMPLE"),IF(I35="COHORTIZACIÓN",IF(COUNTIF(J35,"NO")+COUNTIF(K35,"SI")+COUNTIF(L35,"NO")+COUNTIF(M35,"NO")+(COUNTIF(N35,"QUIRURGICO")-1)+COUNTIF(M64,"NA")+COUNTIF(O35,"NO")+COUNTIF(P35,"NO")+COUNTIF(Q35,"NO")+COUNTIF(R35,"NO")=0,"CUMPLE","NO CUMPLE")))))) -> CUMPLE | T35: CRISTI CONTRERAS
A36: REHABILITACION | B36: =COUNTIFS(G:G,"UCI",H:H,"FISIOTERAPEUTA",S:S,"CUMPLE") -> 0 | C36: =COUNTIFS(G:G,"UCI",H:H,"FISIOTERAPEUTA") -> 0 | D36: =IFERROR(COUNTIFS(G:G,"UCI",H:H,"FISIOTERAPEUTA",S:S,"CUMPLE")/COUNTIFS(G:G,"UCI",H:H,"FISIOTERAPEUTA"),0) -> 0 | E36: 34 | F36: 46048 | G36: UCI | H36: MEDICO ESP | I36: CONTACTO | J36: SI | K36: NO | L36: SI | M36: SI | N36: QUIRURGICO | O36: NO | P36: SI | Q36: SI | R36: SI | S36: =IF(I36="CONTACTO",IF(COUNTIF(J36,"NO")+COUNTIF(K36,"SI")+COUNTIF(L36,"NO")+COUNTIF(M36,"NO")+COUNTIF(R36,"NO")=0,"CUMPLE","NO CUMPLE"),IF(I36="VIA AEREA",IF(COUNTIF(K36,"SI")+COUNTIF(L36,"NO")+(COUNTIF(N36,"ALTA EFICIENCIA")-1)+COUNTIF(R36,"NO")=0,"CUMPLE","NO CUMPLE"),IF(I36="VIA AEREA",IF(COUNTIF(J36,"NO")+COUNTIF(K36,"SI")+COUNTIF(L36,"NO")+(COUNTIF(N36,"ALTA EFICIENCIA")-1)+COUNTIF(R36,"NO")=0,"CUMPLE","NO CUMPLE"),IF(I36="GOTAS",IF(COUNTIF(J36,"NO")+COUNTIF(K36,"SI")+COUNTIF(L36,"NO")+(COUNTIF(N36,"QUIRURGICO")-1)+COUNTIF(R36,"NO")=0,"CUMPLE","NO CUMPLE"),IF(I36="COHORTIZACIÓN",IF(COUNTIF(J36,"NO")+COUNTIF(K36,"SI")+COUNTIF(L36,"NO")+COUNTIF(M36,"NO")+(COUNTIF(N36,"QUIRURGICO")-1)+COUNTIF(M57,"NA")+COUNTIF(O36,"NO")+COUNTIF(P36,"NO")+COUNTIF(Q36,"NO")+COUNTIF(R36,"NO")=0,"CUMPLE","NO CUMPLE")))))) -> CUMPLE | T36: ANDRES GUTIERREZ
A37: MEDICO | B37: =COUNTIFS(G:G,"UCI",H:H,"MEDICO",S:S,"CUMPLE") -> 1 | C37: =COUNTIFS(G:G,"UCI",H:H,"MEDICO") -> 1 | D37: =IFERROR(COUNTIFS(G:G,"UCI",H:H,"MEDICO",S:S,"CUMPLE")/COUNTIFS(G:G,"UCI",H:H,"MEDICO"),0) -> 1 | E37: 35 | F37: 46048 | G37: HOSPITALIZACIÓN | H37: AUXILIAR | I37: CONTACTO | J37: SI | K37: NO | L37: SI | M37: SI | N37: QUIRURGICO | O37: NO | P37: SI | Q37: SI | R37: SI | S37: =IF(I37="CONTACTO",IF(COUNTIF(J37,"NO")+COUNTIF(K37,"SI")+COUNTIF(L37,"NO")+COUNTIF(M37,"NO")+COUNTIF(R37,"NO")=0,"CUMPLE","NO CUMPLE"),IF(I37="VIA AEREA",IF(COUNTIF(K37,"SI")+COUNTIF(L37,"NO")+(COUNTIF(N37,"ALTA EFICIENCIA")-1)+COUNTIF(R37,"NO")=0,"CUMPLE","NO CUMPLE"),IF(I37="VIA AEREA",IF(COUNTIF(J37,"NO")+COUNTIF(K37,"SI")+COUNTIF(L37,"NO")+(COUNTIF(N37,"ALTA EFICIENCIA")-1)+COUNTIF(R37,"NO")=0,"CUMPLE","NO CUMPLE"),IF(I37="GOTAS",IF(COUNTIF(J37,"NO")+COUNTIF(K37,"SI")+COUNTIF(L37,"NO")+(COUNTIF(N37,"QUIRURGICO")-1)+COUNTIF(R37,"NO")=0,"CUMPLE","NO CUMPLE"),IF(I37="COHORTIZACIÓN",IF(COUNTIF(J37,"NO")+COUNTIF(K37,"SI")+COUNTIF(L37,"NO")+COUNTIF(M37,"NO")+(COUNTIF(N37,"QUIRURGICO")-1)+COUNTIF(M58,"NA")+COUNTIF(O37,"NO")+COUNTIF(P37,"NO")+COUNTIF(Q37,"NO")+COUNTIF(R37,"NO")=0,"CUMPLE","NO CUMPLE")))))) -> CUMPLE | T37: GREISY VARELA
A38: MEDICO ESP | B38: =COUNTIFS(G:G,"UCI",H:H,"MEDICO",S:S,"CUMPLE") -> 1 | C38: =COUNTIFS(G:G,"UCI",H:H,"MEDICO") -> 1 | D38: =IFERROR(COUNTIFS(G:G,"UCI",H:H,"MEDICO",S:S,"CUMPLE")/COUNTIFS(G:G,"UCI",H:H,"MEDICO"),0) -> 1 | E38: 36 | F38: 46049 | G38: HOSPITALIZACIÓN | H38: AUXILIAR | I38: CONTACTO | J38: SI | K38: NO | L38: SI | M38: SI | N38: QUIRURGICO | O38: SI | P38: SI | Q38: SI | R38: SI | S38: =IF(I38="CONTACTO",IF(COUNTIF(J38,"NO")+COUNTIF(K38,"SI")+COUNTIF(L38,"NO")+COUNTIF(M38,"NO")+COUNTIF(R38,"NO")=0,"CUMPLE","NO CUMPLE"),IF(I38="VIA AEREA",IF(COUNTIF(K38,"SI")+COUNTIF(L38,"NO")+(COUNTIF(N38,"ALTA EFICIENCIA")-1)+COUNTIF(R38,"NO")=0,"CUMPLE","NO CUMPLE"),IF(I38="VIA AEREA",IF(COUNTIF(J38,"NO")+COUNTIF(K38,"SI")+COUNTIF(L38,"NO")+(COUNTIF(N38,"ALTA EFICIENCIA")-1)+COUNTIF(R38,"NO")=0,"CUMPLE","NO CUMPLE"),IF(I38="GOTAS",IF(COUNTIF(J38,"NO")+COUNTIF(K38,"SI")+COUNTIF(L38,"NO")+(COUNTIF(N38,"QUIRURGICO")-1)+COUNTIF(R38,"NO")=0,"CUMPLE","NO CUMPLE"),IF(I38="COHORTIZACIÓN",IF(COUNTIF(J38,"NO")+COUNTIF(K38,"SI")+COUNTIF(L38,"NO")+COUNTIF(M38,"NO")+(COUNTIF(N38,"QUIRURGICO")-1)+COUNTIF(M59,"NA")+COUNTIF(O38,"NO")+COUNTIF(P38,"NO")+COUNTIF(Q38,"NO")+COUNTIF(R38,"NO")=0,"CUMPLE","NO CUMPLE")))))) -> CUMPLE | T38: MARIA TORO
A39: ADHERENCIA POR TIPO DE AISLAMIENTO URGENCIAS | E39: 37 | F39: 46049 | G39: URGENCIAS | H39: AUXILIAR | I39: VIA AEREA | J39: SI | K39: NO | L39: SI | M39: NA | N39: ALTA EFICIENCIA | O39: NO | P39: SI | Q39: SI | R39: SI | S39: =IF(I39="CONTACTO",IF(COUNTIF(J39,"NO")+COUNTIF(K39,"SI")+COUNTIF(L39,"NO")+COUNTIF(M39,"NO")+COUNTIF(R39,"NO")=0,"CUMPLE","NO CUMPLE"),IF(I39="VIA AEREA",IF(COUNTIF(K39,"SI")+COUNTIF(L39,"NO")+(COUNTIF(N39,"ALTA EFICIENCIA")-1)+COUNTIF(R39,"NO")=0,"CUMPLE","NO CUMPLE"),IF(I39="VIA AEREA",IF(COUNTIF(J39,"NO")+COUNTIF(K39,"SI")+COUNTIF(L39,"NO")+(COUNTIF(N39,"ALTA EFICIENCIA")-1)+COUNTIF(R39,"NO")=0,"CUMPLE","NO CUMPLE"),IF(I39="GOTAS",IF(COUNTIF(J39,"NO")+COUNTIF(K39,"SI")+COUNTIF(L39,"NO")+(COUNTIF(N39,"QUIRURGICO")-1)+COUNTIF(R39,"NO")=0,"CUMPLE","NO CUMPLE"),IF(I39="COHORTIZACIÓN",IF(COUNTIF(J39,"NO")+COUNTIF(K39,"SI")+COUNTIF(L39,"NO")+COUNTIF(M39,"NO")+(COUNTIF(N39,"QUIRURGICO")-1)+COUNTIF(M60,"NA")+COUNTIF(O39,"NO")+COUNTIF(P39,"NO")+COUNTIF(Q39,"NO")+COUNTIF(R39,"NO")=0,"CUMPLE","NO CUMPLE")))))) -> CUMPLE | T39: VANESA HERNANDES
A40: COHORTIZACIÓN | B40: =COUNTIFS(G:G,"URGENCIAS",I:I,"COHORTIZACIÓN",S:S,"CUMPLE") -> 0 | C40: =COUNTIFS(G:G,"URGENCIAS",I:I,"COHORTIZACIÓN") -> 0 | D40: =IFERROR(COUNTIFS(G:G,"URGENCIAS",I:I,"COHORTIZACIÓN",S:S,"CUMPLE")/COUNTIFS(G:G,"URGENCIAS",I:I,"COHORTIZACIÓN"),0) -> 0 | E40: 38 | F40: 46049 | G40: URGENCIAS | H40: AUXILIAR | I40: CONTACTO | J40: SI | K40: NO | L40: SI | M40: SI | N40: QUIRURGICO | O40: NO | P40: SI | Q40: SI | R40: SI | S40: =IF(I40="CONTACTO",IF(COUNTIF(J40,"NO")+COUNTIF(K40,"SI")+COUNTIF(L40,"NO")+COUNTIF(M40,"NO")+COUNTIF(R40,"NO")=0,"CUMPLE","NO CUMPLE"),IF(I40="VIA AEREA",IF(COUNTIF(K40,"SI")+COUNTIF(L40,"NO")+(COUNTIF(N40,"ALTA EFICIENCIA")-1)+COUNTIF(R40,"NO")=0,"CUMPLE","NO CUMPLE"),IF(I40="VIA AEREA",IF(COUNTIF(J40,"NO")+COUNTIF(K40,"SI")+COUNTIF(L40,"NO")+(COUNTIF(N40,"ALTA EFICIENCIA")-1)+COUNTIF(R40,"NO")=0,"CUMPLE","NO CUMPLE"),IF(I40="GOTAS",IF(COUNTIF(J40,"NO")+COUNTIF(K40,"SI")+COUNTIF(L40,"NO")+(COUNTIF(N40,"QUIRURGICO")-1)+COUNTIF(R40,"NO")=0,"CUMPLE","NO CUMPLE"),IF(I40="COHORTIZACIÓN",IF(COUNTIF(J40,"NO")+COUNTIF(K40,"SI")+COUNTIF(L40,"NO")+COUNTIF(M40,"NO")+(COUNTIF(N40,"QUIRURGICO")-1)+COUNTIF(M61,"NA")+COUNTIF(O40,"NO")+COUNTIF(P40,"NO")+COUNTIF(Q40,"NO")+COUNTIF(R40,"NO")=0,"CUMPLE","NO CUMPLE")))))) -> CUMPLE | T40: JOSE MANZANO
...

Sheet listas
A1: SERVICIO | B1: PROFESIONAL | C1: TIPO DE AISLAMIENTO | D1: TIPO DE TAPABOCA
A2: HOSPITALIZACIÓN 2 | B2: AUXILIAR | C2: CONTACTO | D2: QUIRURGICO
A3: HOSPITALIZACIÓN | B3: ENFERMERA (O) | C3: COHORTIZACIÓN | D3: ALTA EFICIENCIA
A4: URGENCIAS | B4: MEDICO | C4: GOTAS | D4: NO
A5: UCI | B5: MEDICO ESPECIALISTA | C5: VIA AEREA | D5: NA
B6: FISIOTERAPEUTA
B7: TERAPEUTA RESPIRATORIO
B8: INTERNO
B9: NUTRICIONISTA
